Workbook

Sheet SAXS
F1: DETALLE PEDIDOS CHINA (PROGRAMACION GENERAL 9-10)
A2: SALIDA | F2: 46253 | G2: 46293 | H2: 46293
A3: ENTRADA | F3: 46294 | G3: 46332 | H3: 46332 | AC3: ¿Columna N (pedidos ARNO) suma al disponible? | AD3: SI
A4: FACTURA | F4: 17035 | G4: 17106 | H4: 17107 | I4: PEDIDO | J4: PEDIDO | K4: PEDIDO | L4: PEDIDO | M4: PEDIDO | N4: PEDIDO | AC4: Meses hasta arribo G/H:
A5: ORIGEN | F5: CHINA | G5: CHINA | H5: CHINA | I5: CHINA | J5: CHINA | K5: CHINA | L5: CHINA | M5: CHINA | N5: CHINA | AC5: (se recalcula con la fecha de hoy) | AD5: =MAX(0,ROUND(($G$3-TODAY())/30.4,2)) -> 0.53
X6: Cálculo automático — Disponible (TOTAL) = STOCK + 17035 (F) + pedidos China G:M + N (si AD3=SI). Revisado 12/10.
A7: SKU | B7: CATEGORIA | C7: ARTICULO | D7: COLOR | E7: STOCK | F7: CANTIDAD | G7: CANTIDAD | H7: CANTIDAD | I7: CANTIDAD | J7: CANTIDAD | K7: CANTIDAD | L7: CANTIDAD | M7: CANTIDAD | N7: CANTIDAD | O7: ANALISIS COMPRA (vs 4 meses, automático) | P7: TOTAL | X7: VENTA PROM. m/mes (Jun-Sep) | Y7: NECESIDAD 4 MESES (m) | Z7: COBERTURA (meses) | AA7: FALTANTE (+) / SOBRANTE (−) m | AB7: SKU DUPLICADO | AC7: VENTA CONCENTRADA (1 mes >50% del período) | AD7: RIESGO QUIEBRE antes del 06/11 (stock+F17035 < venta hasta esa fecha) | AE7: VENTA SUBESTIMADA (stock 0 y Sep < 50% del prom. Feb-Ago) | AF7: VENTA PROM. AJUSTADA m/mes (si hubo quiebre: mayor entre Jun-Sep y Feb-Ago) | AG7: FALTANTE (+)/SOBRANTE (−) AJUSTADO m | AH7: SEÑAL AJUSTADA
A8: 4931098-9999 | B8: CAPELLADA | C8: CALI | D8: NEGRO | E8: 10430 | K8: 9000 | L8: 5000 | O8: =IF(A8="","SIN SKU — cargar código para calcular",IF(X8="","SIN HISTORIAL DE VENTAS — artículo nuevo o código distinto en Ventas",IF(X8=0,IF(P8>0,"SIN VENTAS Jun-Sep — no comprar ("&TEXT(P8,"#,##0")&" m disponibles)","SIN VENTAS Jun-Sep — no comprar"),IF(AA8>0.1*Y8,"COMPRAR — faltan "&TEXT(AA8,"#,##0")&" m para 4 meses"&IF(P8-E8>0," (ya contando pedidos)",""),IF(AND(-AA8>0.1*Y8,SUM(I8:M8)+IF($AD$3="SI",SUM(N8),0)>0),"PEDIR MENOS — sobran "&TEXT(-AA8,"#,##0")&" m; revisar pedidos sin facturar ("&TEXT(SUM(I8:M8)+IF($AD$3="SI",SUM(N8),0),"#,##0")&" m)",IF(Z8>8,"SOBRESTOCK — "&TEXT(Z8,"0.0")&" meses de cobertura","OK — cubierto ("&TEXT(Z8,"0.0")&" meses)")))))) -> PEDIR MENOS — sobran 3,623 m; revisar pedidos sin facturar (14,000 m) | P8: =E8+N(F8)+SUM(G8:M8)+IF($AD$3="SI",SUM(N8),0) -> 24430 | Q8: 10000 | X8: =IFERROR(VLOOKUP($A8,Ventas!$A$2:$L$5000,12,FALSE()),"") -> 5201.75 | Y8: =IF(X8="","",ROUND(X8*4,0)) -> 20807 | Z8: =IF(OR(X8="",X8=0),"",ROUND(P8/X8,1)) -> 4.7 | AA8: =IF(Y8="","",Y8-P8) -> -3623 | AB8: =IF(A8="","",IF(COUNTIF($A$8:$A$670,A8)>1,"DUPLICADO","")) | AC8: {=IF(AH8<>"COMPRAR","",IF(MAX(INDEX(Ventas!$G$2:$G$5000,MATCH($A8,Ventas!$A$2:$A$5000,0)),INDEX(Ventas!$H$2:$H$5000,MATCH($A8,Ventas!$A$2:$A$5000,0)),INDEX(Ventas!$I$2:$I$5000,MATCH($A8,Ventas!$A$2:$A$5000,0)),INDEX(Ventas!$J$2:$J$5000,MATCH($A8,Ventas!$A$2:$A$5000,0)))>0.5*AF8*4,"1 mes = "&TEXT(MAX(INDEX(Ventas!$G$2:$G$5000,MATCH($A8,Ventas!$A$2:$A$5000,0)),INDEX(Ventas!$H$2:$H$5000,MATCH($A8,Ventas!$A$2:$A$5000,0)),INDEX(Ventas!$I$2:$I$5000,MATCH($A8,Ventas!$A$2:$A$5000,0)),INDEX(Ventas!$J$2:$J$5000,MATCH($A8,Ventas!$A$2:$A$5000,0)))/(AF8*4),"0%")&" de 4 meses",""))} | AD8: =IF(OR(X8="",X8=0),"",IF(E8+N(F8)<X8*$AD$5,"SÍ — "&TEXT(E8+N(F8),"#,##0")&" m vs "&TEXT(X8*$AD$5,"#,##0")&" m","")) | AE8: {=IF(X8="","",IF(AND(E8=0,AVERAGE(INDEX(Ventas!$C$2:$I$5000,MATCH($A8,Ventas!$A$2:$A$5000,0),0))>0,INDEX(Ventas!$J$2:$J$5000,MATCH($A8,Ventas!$A$2:$A$5000,0))<0.5*AVERAGE(INDEX(Ventas!$C$2:$I$5000,MATCH($A8,Ventas!$A$2:$A$5000,0),0))),"SÍ — stock 0 y Sep cayó (prom Feb-Ago "&TEXT(AVERAGE(INDEX(Ventas!$C$2:$I$5000,MATCH($A8,Ventas!$A$2:$A$5000,0),0)),"#,##0")&")",""))} | AF8: {=IF(X8="","",IF(AE8<>"",MAX(X8,AVERAGE(INDEX(Ventas!$C$2:$I$5000,MATCH($A8,Ventas!$A$2:$A$5000,0),0))),X8))} -> 5201.75 | AG8: =IF(AF8="","",ROUND(AF8*4,0)-P8) -> -3623 | AH8: =IF(A8="","",IF(AF8="","SIN HISTORIAL",IF(AF8=0,"SIN VENTAS",IF(AG8>0.1*ROUND(AF8*4,0),"COMPRAR",IF(AND(-AG8>0.1*ROUND(AF8*4,0),SUM(I8:M8)+IF($AD$3="SI",SUM(N8),0)>0),"PEDIR MENOS",IF(P8/AF8>8,"SOBRESTOCK","OK")))))) -> PEDIR MENOS
A9: 4931098-0000 | B9: CAPELLADA | C9: CALI | D9: BLANCO | E9: 200 | H9: 2033 | K9: 2000 | O9: =IF(A9="","SIN SKU — cargar código para calcular",IF(X9="","SIN HISTORIAL DE VENTAS — artículo nuevo o código distinto en Ventas",IF(X9=0,IF(P9>0,"SIN VENTAS Jun-Sep — no comprar ("&TEXT(P9,"#,##0")&" m disponibles)","SIN VENTAS Jun-Sep — no comprar"),IF(AA9>0.1*Y9,"COMPRAR — faltan "&TEXT(AA9,"#,##0")&" m para 4 meses"&IF(P9-E9>0," (ya contando pedidos)",""),IF(AND(-AA9>0.1*Y9,SUM(I9:M9)+IF($AD$3="SI",SUM(N9),0)>0),"PEDIR MENOS — sobran "&TEXT(-AA9,"#,##0")&" m; revisar pedidos sin facturar ("&TEXT(SUM(I9:M9)+IF($AD$3="SI",SUM(N9),0),"#,##0")&" m)",IF(Z9>8,"SOBRESTOCK — "&TEXT(Z9,"0.0")&" meses de cobertura","OK — cubierto ("&TEXT(Z9,"0.0")&" meses)")))))) -> PEDIR MENOS — sobran 522 m; revisar pedidos sin facturar (2,000 m) | P9: =E9+N(F9)+SUM(G9:M9)+IF($AD$3="SI",SUM(N9),0) -> 4233 | X9: =IFERROR(VLOOKUP($A9,Ventas!$A$2:$L$5000,12,FALSE()),"") -> 927.75 | Y9: =IF(X9="","",ROUND(X9*4,0)) -> 3711 | Z9: =IF(OR(X9="",X9=0),"",ROUND(P9/X9,1)) -> 4.6 | AA9: =IF(Y9="","",Y9-P9) -> -522 | AB9: =IF(A9="","",IF(COUNTIF($A$8:$A$670,A9)>1,"DUPLICADO","")) | AC9: {=IF(AH9<>"COMPRAR","",IF(MAX(INDEX(Ventas!$G$2:$G$5000,MATCH($A9,Ventas!$A$2:$A$5000,0)),INDEX(Ventas!$H$2:$H$5000,MATCH($A9,Ventas!$A$2:$A$5000,0)),INDEX(Ventas!$I$2:$I$5000,MATCH($A9,Ventas!$A$2:$A$5000,0)),INDEX(Ventas!$J$2:$J$5000,MATCH($A9,Ventas!$A$2:$A$5000,0)))>0.5*AF9*4,"1 mes = "&TEXT(MAX(INDEX(Ventas!$G$2:$G$5000,MATCH($A9,Ventas!$A$2:$A$5000,0)),INDEX(Ventas!$H$2:$H$5000,MATCH($A9,Ventas!$A$2:$A$5000,0)),INDEX(Ventas!$I$2:$I$5000,MATCH($A9,Ventas!$A$2:$A$5000,0)),INDEX(Ventas!$J$2:$J$5000,MATCH($A9,Ventas!$A$2:$A$5000,0)))/(AF9*4),"0%")&" de 4 meses",""))} | AD9: =IF(OR(X9="",X9=0),"",IF(E9+N(F9)<X9*$AD$5,"SÍ — "&TEXT(E9+N(F9),"#,##0")&" m vs "&TEXT(X9*$AD$5,"#,##0")&" m","")) -> SÍ — 200 m vs 492 m | AE9: {=IF(X9="","",IF(AND(E9=0,AVERAGE(INDEX(Ventas!$C$2:$I$5000,MATCH($A9,Ventas!$A$2:$A$5000,0),0))>0,INDEX(Ventas!$J$2:$J$5000,MATCH($A9,Ventas!$A$2:$A$5000,0))<0.5*AVERAGE(INDEX(Ventas!$C$2:$I$5000,MATCH($A9,Ventas!$A$2:$A$5000,0),0))),"SÍ — stock 0 y Sep cayó (prom Feb-Ago "&TEXT(AVERAGE(INDEX(Ventas!$C$2:$I$5000,MATCH($A9,Ventas!$A$2:$A$5000,0),0)),"#,##0")&")",""))} | AF9: {=IF(X9="","",IF(AE9<>"",MAX(X9,AVERAGE(INDEX(Ventas!$C$2:$I$5000,MATCH($A9,Ventas!$A$2:$A$5000,0),0))),X9))} -> 927.75 | AG9: =IF(AF9="","",ROUND(AF9*4,0)-P9) -> -522 | AH9: =IF(A9="","",IF(AF9="","SIN HISTORIAL",IF(AF9=0,"SIN VENTAS",IF(AG9>0.1*ROUND(AF9*4,0),"COMPRAR",IF(AND(-AG9>0.1*ROUND(AF9*4,0),SUM(I9:M9)+IF($AD$3="SI",SUM(N9),0)>0),"PEDIR MENOS",IF(P9/AF9>8,"SOBRESTOCK","OK")))))) -> PEDIR MENOS
A10: 4931098-0697 | B10: CAPELLADA | C10: CALI | D10: SUELA OSCURO D/T | E10: 1120 | O10: =IF(A10="","SIN SKU — cargar código para calcular",IF(X10="","SIN HISTORIAL DE VENTAS — artículo nuevo o código distinto en Ventas",IF(X10=0,IF(P10>0,"SIN VENTAS Jun-Sep — no comprar ("&TEXT(P10,"#,##0")&" m disponibles)","SIN VENTAS Jun-Sep — no comprar"),IF(AA10>0.1*Y10,"COMPRAR — faltan "&TEXT(AA10,"#,##0")&" m para 4 meses"&IF(P10-E10>0," (ya contando pedidos)",""),IF(AND(-AA10>0.1*Y10,SUM(I10:M10)+IF($AD$3="SI",SUM(N10),0)>0),"PEDIR MENOS — sobran "&TEXT(-AA10,"#,##0")&" m; revisar pedidos sin facturar ("&TEXT(SUM(I10:M10)+IF($AD$3="SI",SUM(N10),0),"#,##0")&" m)",IF(Z10>8,"SOBRESTOCK — "&TEXT(Z10,"0.0")&" meses de cobertura","OK — cubierto ("&TEXT(Z10,"0.0")&" meses)")))))) -> OK — cubierto (7.0 meses) | P10: =E10+N(F10)+SUM(G10:M10)+IF($AD$3="SI",SUM(N10),0) -> 1120 | X10: =IFERROR(VLOOKUP($A10,Ventas!$A$2:$L$5000,12,FALSE()),"") -> 160.75 | Y10: =IF(X10="","",ROUND(X10*4,0)) -> 643 | Z10: =IF(OR(X10="",X10=0),"",ROUND(P10/X10,1)) -> 7 | AA10: =IF(Y10="","",Y10-P10) -> -477 | AB10: =IF(A10="","",IF(COUNTIF($A$8:$A$670,A10)>1,"DUPLICADO","")) | AC10: {=IF(AH10<>"COMPRAR","",IF(MAX(INDEX(Ventas!$G$2:$G$5000,MATCH($A10,Ventas!$A$2:$A$5000,0)),INDEX(Ventas!$H$2:$H$5000,MATCH($A10,Ventas!$A$2:$A$5000,0)),INDEX(Ventas!$I$2:$I$5000,MATCH($A10,Ventas!$A$2:$A$5000,0)),INDEX(Ventas!$J$2:$J$5000,MATCH($A10,Ventas!$A$2:$A$5000,0)))>0.5*AF10*4,"1 mes = "&TEXT(MAX(INDEX(Ventas!$G$2:$G$5000,MATCH($A10,Ventas!$A$2:$A$5000,0)),INDEX(Ventas!$H$2:$H$5000,MATCH($A10,Ventas!$A$2:$A$5000,0)),INDEX(Ventas!$I$2:$I$5000,MATCH($A10,Ventas!$A$2:$A$5000,0)),INDEX(Ventas!$J$2:$J$5000,MATCH($A10,Ventas!$A$2:$A$5000,0)))/(AF10*4),"0%")&" de 4 meses",""))} | AD10: =IF(OR(X10="",X10=0),"",IF(E10+N(F10)<X10*$AD$5,"SÍ — "&TEXT(E10+N(F10),"#,##0")&" m vs "&TEXT(X10*$AD$5,"#,##0")&" m","")) | AE10: {=IF(X10="","",IF(AND(E10=0,AVERAGE(INDEX(Ventas!$C$2:$I$5000,MATCH($A10,Ventas!$A$2:$A$5000,0),0))>0,INDEX(Ventas!$J$2:$J$5000,MATCH($A10,Ventas!$A$2:$A$5000,0))<0.5*AVERAGE(INDEX(Ventas!$C$2:$I$5000,MATCH($A10,Ventas!$A$2:$A$5000,0),0))),"SÍ — stock 0 y Sep cayó (prom Feb-Ago "&TEXT(AVERAGE(INDEX(Ventas!$C$2:$I$5000,MATCH($A10,Ventas!$A$2:$A$5000,0),0)),"#,##0")&")",""))} | AF10: {=IF(X10="","",IF(AE10<>"",MAX(X10,AVERAGE(INDEX(Ventas!$C$2:$I$5000,MATCH($A10,Ventas!$A$2:$A$5000,0),0))),X10))} -> 160.75 | AG10: =IF(AF10="","",ROUND(AF10*4,0)-P10) -> -477 | AH10: =IF(A10="","",IF(AF10="","SIN HISTORIAL",IF(AF10=0,"SIN VENTAS",IF(AG10>0.1*ROUND(AF10*4,0),"COMPRAR",IF(AND(-AG10>0.1*ROUND(AF10*4,0),SUM(I10:M10)+IF($AD$3="SI",SUM(N10),0)>0),"PEDIR MENOS",IF(P10/AF10>8,"SOBRESTOCK","OK")))))) -> OK
A11: 4931098-0597 | B11: CAPELLADA | C11: CALI | D11: SUELA D/T | E11: 0 | L11: 1000 | O11: =IF(A11="","SIN SKU — cargar código para calcular",IF(X11="","SIN HISTORIAL DE VENTAS — artículo nuevo o código distinto en Ventas",IF(X11=0,IF(P11>0,"SIN VENTAS Jun-Sep — no comprar ("&TEXT(P11,"#,##0")&" m disponibles)","SIN VENTAS Jun-Sep — no comprar"),IF(AA11>0.1*Y11,"COMPRAR — faltan "&TEXT(AA11,"#,##0")&" m para 4 meses"&IF(P11-E11>0," (ya contando pedidos)",""),IF(AND(-AA11>0.1*Y11,SUM(I11:M11)+IF($AD$3="SI",SUM(N11),0)>0),"PEDIR MENOS — sobran "&TEXT(-AA11,"#,##0")&" m; revisar pedidos sin facturar ("&TEXT(SUM(I11:M11)+IF($AD$3="SI",SUM(N11),0),"#,##0")&" m)",IF(Z11>8,"SOBRESTOCK — "&TEXT(Z11,"0.0")&" meses de cobertura","OK — cubierto ("&TEXT(Z11,"0.0")&" meses)")))))) -> OK — cubierto (3.8 meses) | P11: =E11+N(F11)+SUM(G11:M11)+IF($AD$3="SI",SUM(N11),0) -> 1000 | X11: =IFERROR(VLOOKUP($A11,Ventas!$A$2:$L$5000,12,FALSE()),"") -> 261.25 | Y11: =IF(X11="","",ROUND(X11*4,0)) -> 1045 | Z11: =IF(OR(X11="",X11=0),"",ROUND(P11/X11,1)) -> 3.8 | AA11: =IF(Y11="","",Y11-P11) -> 45 | AB11: =IF(A11="","",IF(COUNTIF($A$8:$A$670,A11)>1,"DUPLICADO","")) | AC11: {=IF(AH11<>"COMPRAR","",IF(MAX(INDEX(Ventas!$G$2:$G$5000,MATCH($A11,Ventas!$A$2:$A$5000,0)),INDEX(Ventas!$H$2:$H$5000,MATCH($A11,Ventas!$A$2:$A$5000,0)),INDEX(Ventas!$I$2:$I$5000,MATCH($A11,Ventas!$A$2:$A$5000,0)),INDEX(Ventas!$J$2:$J$5000,MATCH($A11,Ventas!$A$2:$A$5000,0)))>0.5*AF11*4,"1 mes = "&TEXT(MAX(INDEX(Ventas!$G$2:$G$5000,MATCH($A11,Ventas!$A$2:$A$5000,0)),INDEX(Ventas!$H$2:$H$5000,MATCH($A11,Ventas!$A$2:$A$5000,0)),INDEX(Ventas!$I$2:$I$5000,MATCH($A11,Ventas!$A$2:$A$5000,0)),INDEX(Ventas!$J$2:$J$5000,MATCH($A11,Ventas!$A$2:$A$5000,0)))/(AF11*4),"0%")&" de 4 meses",""))} | AD11: =IF(OR(X11="",X11=0),"",IF(E11+N(F11)<X11*$AD$5,"SÍ — "&TEXT(E11+N(F11),"#,##0")&" m vs "&TEXT(X11*$AD$5,"#,##0")&" m","")) -> SÍ — 0 m vs 138 m | AE11: {=IF(X11="","",IF(AND(E11=0,AVERAGE(INDEX(Ventas!$C$2:$I$5000,MATCH($A11,Ventas!$A$2:$A$5000,0),0))>0,INDEX(Ventas!$J$2:$J$5000,MATCH($A11,Ventas!$A$2:$A$5000,0))<0.5*AVERAGE(INDEX(Ventas!$C$2:$I$5000,MATCH($A11,Ventas!$A$2:$A$5000,0),0))),"SÍ — stock 0 y Sep cayó (prom Feb-Ago "&TEXT(AVERAGE(INDEX(Ventas!$C$2:$I$5000,MATCH($A11,Ventas!$A$2:$A$5000,0),0)),"#,##0")&")",""))} -> SÍ — stock 0 y Sep cayó (prom Feb-Ago 344) | AF11: {=IF(X11="","",IF(AE11<>"",MAX(X11,AVERAGE(INDEX(Ventas!$C$2:$I$5000,MATCH($A11,Ventas!$A$2:$A$5000,0),0))),X11))} -> 343.57143 | AG11: =IF(AF11="","",ROUND(AF11*4,0)-P11) -> 374 | AH11: =IF(A11="","",IF(AF11="","SIN HISTORIAL",IF(AF11=0,"SIN VENTAS",IF(AG11>0.1*ROUND(AF11*4,0),"COMPRAR",IF(AND(-AG11>0.1*ROUND(AF11*4,0),SUM(I11:M11)+IF($AD$3="SI",SUM(N11),0)>0),"PEDIR MENOS",IF(P11/AF11>8,"SOBRESTOCK","OK")))))) -> COMPRAR
A12: 4931098-0047 | B12: CAPELLADA | C12: CALI | D12: VISON | E12: 40 | L12: 800 | O12: =IF(A12="","SIN SKU — cargar código para calcular",IF(X12="","SIN HISTORIAL DE VENTAS — artículo nuevo o código distinto en Ventas",IF(X12=0,IF(P12>0,"SIN VENTAS Jun-Sep — no comprar ("&TEXT(P12,"#,##0")&" m disponibles)","SIN VENTAS Jun-Sep — no comprar"),IF(AA12>0.1*Y12,"COMPRAR — faltan "&TEXT(AA12,"#,##0")&" m para 4 meses"&IF(P12-E12>0," (ya contando pedidos)",""),IF(AND(-AA12>0.1*Y12,SUM(I12:M12)+IF($AD$3="SI",SUM(N12),0)>0),"PEDIR MENOS — sobran "&TEXT(-AA12,"#,##0")&" m; revisar pedidos sin facturar ("&TEXT(SUM(I12:M12)+IF($AD$3="SI",SUM(N12),0),"#,##0")&" m)",IF(Z12>8,"SOBRESTOCK — "&TEXT(Z12,"0.0")&" meses de cobertura","OK — cubierto ("&TEXT(Z12,"0.0")&" meses)")))))) -> PEDIR MENOS — sobran 560 m; revisar pedidos sin facturar (800 m) | P12: =E12+N(F12)+SUM(G12:M12)+IF($AD$3="SI",SUM(N12),0) -> 840 | X12: =IFERROR(VLOOKUP($A12,Ventas!$A$2:$L$5000,12,FALSE()),"") -> 70 | Y12: =IF(X12="","",ROUND(X12*4,0)) -> 280 | Z12: =IF(OR(X12="",X12=0),"",ROUND(P12/X12,1)) -> 12 | AA12: =IF(Y12="","",Y12-P12) -> -560 | AB12: =IF(A12="","",IF(COUNTIF($A$8:$A$670,A12)>1,"DUPLICADO","")) | AC12: {=IF(AH12<>"COMPRAR","",IF(MAX(INDEX(Ventas!$G$2:$G$5000,MATCH($A12,Ventas!$A$2:$A$5000,0)),INDEX(Ventas!$H$2:$H$5000,MATCH($A12,Ventas!$A$2:$A$5000,0)),INDEX(Ventas!$I$2:$I$5000,MATCH($A12,Ventas!$A$2:$A$5000,0)),INDEX(Ventas!$J$2:$J$5000,MATCH($A12,Ventas!$A$2:$A$5000,0)))>0.5*AF12*4,"1 mes = "&TEXT(MAX(INDEX(Ventas!$G$2:$G$5000,MATCH($A12,Ventas!$A$2:$A$5000,0)),INDEX(Ventas!$H$2:$H$5000,MATCH($A12,Ventas!$A$2:$A$5000,0)),INDEX(Ventas!$I$2:$I$5000,MATCH($A12,Ventas!$A$2:$A$5000,0)),INDEX(Ventas!$J$2:$J$5000,MATCH($A12,Ventas!$A$2:$A$5000,0)))/(AF12*4),"0%")&" de 4 meses",""))} | AD12: =IF(OR(X12="",X12=0),"",IF(E12+N(F12)<X12*$AD$5,"SÍ — "&TEXT(E12+N(F12),"#,##0")&" m vs "&TEXT(X12*$AD$5,"#,##0")&" m","")) | AE12: {=IF(X12="","",IF(AND(E12=0,AVERAGE(INDEX(Ventas!$C$2:$I$5000,MATCH($A12,Ventas!$A$2:$A$5000,0),0))>0,INDEX(Ventas!$J$2:$J$5000,MATCH($A12,Ventas!$A$2:$A$5000,0))<0.5*AVERAGE(INDEX(Ventas!$C$2:$I$5000,MATCH($A12,Ventas!$A$2:$A$5000,0),0))),"SÍ — stock 0 y Sep cayó (prom Feb-Ago "&TEXT(AVERAGE(INDEX(Ventas!$C$2:$I$5000,MATCH($A12,Ventas!$A$2:$A$5000,0),0)),"#,##0")&")",""))} | AF12: {=IF(X12="","",IF(AE12<>"",MAX(X12,AVERAGE(INDEX(Ventas!$C$2:$I$5000,MATCH($A12,Ventas!$A$2:$A$5000,0),0))),X12))} -> 70 | AG12: =IF(AF12="","",ROUND(AF12*4,0)-P12) -> -560 | AH12: =IF(A12="","",IF(AF12="","SIN HISTORIAL",IF(AF12=0,"SIN VENTAS",IF(AG12>0.1*ROUND(AF12*4,0),"COMPRAR",IF(AND(-AG12>0.1*ROUND(AF12*4,0),SUM(I12:M12)+IF($AD$3="SI",SUM(N12),0)>0),"PEDIR MENOS",IF(P12/AF12>8,"SOBRESTOCK","OK")))))) -> PEDIR MENOS
B13: CAPELLADA | C13: CALI | D13: BORDO | L13: 800 | O13: =IF(A13="","SIN SKU — cargar código para calcular",IF(X13="","SIN HISTORIAL DE VENTAS — artículo nuevo o código distinto en Ventas",IF(X13=0,IF(P13>0,"SIN VENTAS Jun-Sep — no comprar ("&TEXT(P13,"#,##0")&" m disponibles)","SIN VENTAS Jun-Sep — no comprar"),IF(AA13>0.1*Y13,"COMPRAR — faltan "&TEXT(AA13,"#,##0")&" m para 4 meses"&IF(P13-E13>0," (ya contando pedidos)",""),IF(AND(-AA13>0.1*Y13,SUM(I13:M13)+IF($AD$3="SI",SUM(N13),0)>0),"PEDIR MENOS — sobran "&TEXT(-AA13,"#,##0")&" m; revisar pedidos sin facturar ("&TEXT(SUM(I13:M13)+IF($AD$3="SI",SUM(N13),0),"#,##0")&" m)",IF(Z13>8,"SOBRESTOCK — "&TEXT(Z13,"0.0")&" meses de cobertura","OK — cubierto ("&TEXT(Z13,"0.0")&" meses)")))))) -> SIN SKU — cargar código para calcular | P13: =E13+N(F13)+SUM(G13:M13)+IF($AD$3="SI",SUM(N13),0) -> 800 | X13: =IFERROR(VLOOKUP($A13,Ventas!$A$2:$L$5000,12,FALSE()),"") | Y13: =IF(X13="","",ROUND(X13*4,0)) | Z13: =IF(OR(X13="",X13=0),"",ROUND(P13/X13,1)) | AA13: =IF(Y13="","",Y13-P13) | AB13: =IF(A13="","",IF(COUNTIF($A$8:$A$670,A13)>1,"DUPLICADO","")) | AC13: {=IF(AH13<>"COMPRAR","",IF(MAX(INDEX(Ventas!$G$2:$G$5000,MATCH($A13,Ventas!$A$2:$A$5000,0)),INDEX(Ventas!$H$2:$H$5000,MATCH($A13,Ventas!$A$2:$A$5000,0)),INDEX(Ventas!$I$2:$I$5000,MATCH($A13,Ventas!$A$2:$A$5000,0)),INDEX(Ventas!$J$2:$J$5000,MATCH($A13,Ventas!$A$2:$A$5000,0)))>0.5*AF13*4,"1 mes = "&TEXT(MAX(INDEX(Ventas!$G$2:$G$5000,MATCH($A13,Ventas!$A$2:$A$5000,0)),INDEX(Ventas!$H$2:$H$5000,MATCH($A13,Ventas!$A$2:$A$5000,0)),INDEX(Ventas!$I$2:$I$5000,MATCH($A13,Ventas!$A$2:$A$5000,0)),INDEX(Ventas!$J$2:$J$5000,MATCH($A13,Ventas!$A$2:$A$5000,0)))/(AF13*4),"0%")&" de 4 meses",""))} | AD13: =IF(OR(X13="",X13=0),"",IF(E13+N(F13)<X13*$AD$5,"SÍ — "&TEXT(E13+N(F13),"#,##0")&" m vs "&TEXT(X13*$AD$5,"#,##0")&" m","")) | AE13: {=IF(X13="","",IF(AND(E13=0,AVERAGE(INDEX(Ventas!$C$2:$I$5000,MATCH($A13,Ventas!$A$2:$A$5000,0),0))>0,INDEX(Ventas!$J$2:$J$5000,MATCH($A13,Ventas!$A$2:$A$5000,0))<0.5*AVERAGE(INDEX(Ventas!$C$2:$I$5000,MATCH($A13,Ventas!$A$2:$A$5000,0),0))),"SÍ — stock 0 y Sep cayó (prom Feb-Ago "&TEXT(AVERAGE(INDEX(Ventas!$C$2:$I$5000,MATCH($A13,Ventas!$A$2:$A$5000,0),0)),"#,##0")&")",""))} | AF13: {=IF(X13="","",IF(AE13<>"",MAX(X13,AVERAGE(INDEX(Ventas!$C$2:$I$5000,MATCH($A13,Ventas!$A$2:$A$5000,0),0))),X13))} | AG13: =IF(AF13="","",ROUND(AF13*4,0)-P13) | AH13: =IF(A13="","",IF(AF13="","SIN HISTORIAL",IF(AF13=0,"SIN VENTAS",IF(AG13>0.1*ROUND(AF13*4,0),"COMPRAR",IF(AND(-AG13>0.1*ROUND(AF13*4,0),SUM(I13:M13)+IF($AD$3="SI",SUM(N13),0)>0),"PEDIR MENOS",IF(P13/AF13>8,"SOBRESTOCK","OK"))))))
A14: 4931098-0159 | B14: CAPELLADA | C14: CALI | D14: NUDE | E14: 1084 | O14: =IF(A14="","SIN SKU — cargar código para calcular",IF(X14="","SIN HISTORIAL DE VENTAS — artículo nuevo o código distinto en Ventas",IF(X14=0,IF(P14>0,"SIN VENTAS Jun-Sep — no comprar ("&TEXT(P14,"#,##0")&" m disponibles)","SIN VENTAS Jun-Sep — no comprar"),IF(AA14>0.1*Y14,"COMPRAR — faltan "&TEXT(AA14,"#,##0")&" m para 4 meses"&IF(P14-E14>0," (ya contando pedidos)",""),IF(AND(-AA14>0.1*Y14,SUM(I14:M14)+IF($AD$3="SI",SUM(N14),0)>0),"PEDIR MENOS — sobran "&TEXT(-AA14,"#,##0")&" m; revisar pedidos sin facturar ("&TEXT(SUM(I14:M14)+IF($AD$3="SI",SUM(N14),0),"#,##0")&" m)",IF(Z14>8,"SOBRESTOCK — "&TEXT(Z14,"0.0")&" meses de cobertura","OK — cubierto ("&TEXT(Z14,"0.0")&" meses)")))))) -> SOBRESTOCK — 15.5 meses de cobertura | P14: =E14+N(F14)+SUM(G14:M14)+IF($AD$3="SI",SUM(N14),0) -> 1084 | X14: =IFERROR(VLOOKUP($A14,Ventas!$A$2:$L$5000,12,FALSE()),"") -> 70 | Y14: =IF(X14="","",ROUND(X14*4,0)) -> 280 | Z14: =IF(OR(X14="",X14=0),"",ROUND(P14/X14,1)) -> 15.5 | AA14: =IF(Y14="","",Y14-P14) -> -804 | AB14: =IF(A14="","",IF(COUNTIF($A$8:$A$670,A14)>1,"DUPLICADO","")) | AC14: {=IF(AH14<>"COMPRAR","",IF(MAX(INDEX(Ventas!$G$2:$G$5000,MATCH($A14,Ventas!$A$2:$A$5000,0)),INDEX(Ventas!$H$2:$H$5000,MATCH($A14,Ventas!$A$2:$A$5000,0)),INDEX(Ventas!$I$2:$I$5000,MATCH($A14,Ventas!$A$2:$A$5000,0)),INDEX(Ventas!$J$2:$J$5000,MATCH($A14,Ventas!$A$2:$A$5000,0)))>0.5*AF14*4,"1 mes = "&TEXT(MAX(INDEX(Ventas!$G$2:$G$5000,MATCH($A14,Ventas!$A$2:$A$5000,0)),INDEX(Ventas!$H$2:$H$5000,MATCH($A14,Ventas!$A$2:$A$5000,0)),INDEX(Ventas!$I$2:$I$5000,MATCH($A14,Ventas!$A$2:$A$5000,0)),INDEX(Ventas!$J$2:$J$5000,MATCH($A14,Ventas!$A$2:$A$5000,0)))/(AF14*4),"0%")&" de 4 meses",""))} | AD14: =IF(OR(X14="",X14=0),"",IF(E14+N(F14)<X14*$AD$5,"SÍ — "&TEXT(E14+N(F14),"#,##0")&" m vs "&TEXT(X14*$AD$5,"#,##0")&" m","")) | AE14: {=IF(X14="","",IF(AND(E14=0,AVERAGE(INDEX(Ventas!$C$2:$I$5000,MATCH($A14,Ventas!$A$2:$A$5000,0),0))>0,INDEX(Ventas!$J$2:$J$5000,MATCH($A14,Ventas!$A$2:$A$5000,0))<0.5*AVERAGE(INDEX(Ventas!$C$2:$I$5000,MATCH($A14,Ventas!$A$2:$A$5000,0),0))),"SÍ — stock 0 y Sep cayó (prom Feb-Ago "&TEXT(AVERAGE(INDEX(Ventas!$C$2:$I$5000,MATCH($A14,Ventas!$A$2:$A$5000,0),0)),"#,##0")&")",""))} | AF14: {=IF(X14="","",IF(AE14<>"",MAX(X14,AVERAGE(INDEX(Ventas!$C$2:$I$5000,MATCH($A14,Ventas!$A$2:$A$5000,0),0))),X14))} -> 70 | AG14: =IF(AF14="","",ROUND(AF14*4,0)-P14) -> -804 | AH14: =IF(A14="","",IF(AF14="","SIN HISTORIAL",IF(AF14=0,"SIN VENTAS",IF(AG14>0.1*ROUND(AF14*4,0),"COMPRAR",IF(AND(-AG14>0.1*ROUND(AF14*4,0),SUM(I14:M14)+IF($AD$3="SI",SUM(N14),0)>0),"PEDIR MENOS",IF(P14/AF14>8,"SOBRESTOCK","OK")))))) -> SOBRESTOCK
A15: 4931098-0198 | B15: CAPELLADA | C15: CALI | D15: MANTECA | E15: 1960 | O15: =IF(A15="","SIN SKU — cargar código para calcular",IF(X15="","SIN HISTORIAL DE VENTAS — artículo nuevo o código distinto en Ventas",IF(X15=0,IF(P15>0,"SIN VENTAS Jun-Sep — no comprar ("&TEXT(P15,"#,##0")&" m disponibles)","SIN VENTAS Jun-Sep — no comprar"),IF(AA15>0.1*Y15,"COMPRAR — faltan "&TEXT(AA15,"#,##0")&" m para 4 meses"&IF(P15-E15>0," (ya contando pedidos)",""),IF(AND(-AA15>0.1*Y15,SUM(I15:M15)+IF($AD$3="SI",SUM(N15),0)>0),"PEDIR MENOS — sobran "&TEXT(-AA15,"#,##0")&" m; revisar pedidos sin facturar ("&TEXT(SUM(I15:M15)+IF($AD$3="SI",SUM(N15),0),"#,##0")&" m)",IF(Z15>8,"SOBRESTOCK — "&TEXT(Z15,"0.0")&" meses de cobertura","OK — cubierto ("&TEXT(Z15,"0.0")&" meses)")))))) -> SOBRESTOCK — 11.5 meses de cobertura | P15: =E15+N(F15)+SUM(G15:M15)+IF($AD$3="SI",SUM(N15),0) -> 1960 | X15: =IFERROR(VLOOKUP($A15,Ventas!$A$2:$L$5000,12,FALSE()),"") -> 170 | Y15: =IF(X15="","",ROUND(X15*4,0)) -> 680 | Z15: =IF(OR(X15="",X15=0),"",ROUND(P15/X15,1)) -> 11.5 | AA15: =IF(Y15="","",Y15-P15) -> -1280 | AB15: =IF(A15="","",IF(COUNTIF($A$8:$A$670,A15)>1,"DUPLICADO","")) | AC15: {=IF(AH15<>"COMPRAR","",IF(MAX(INDEX(Ventas!$G$2:$G$5000,MATCH($A15,Ventas!$A$2:$A$5000,0)),INDEX(Ventas!$H$2:$H$5000,MATCH($A15,Ventas!$A$2:$A$5000,0)),INDEX(Ventas!$I$2:$I$5000,MATCH($A15,Ventas!$A$2:$A$5000,0)),INDEX(Ventas!$J$2:$J$5000,MATCH($A15,Ventas!$A$2:$A$5000,0)))>0.5*AF15*4,"1 mes = "&TEXT(MAX(INDEX(Ventas!$G$2:$G$5000,MATCH($A15,Ventas!$A$2:$A$5000,0)),INDEX(Ventas!$H$2:$H$5000,MATCH($A15,Ventas!$A$2:$A$5000,0)),INDEX(Ventas!$I$2:$I$5000,MATCH($A15,Ventas!$A$2:$A$5000,0)),INDEX(Ventas!$J$2:$J$5000,MATCH($A15,Ventas!$A$2:$A$5000,0)))/(AF15*4),"0%")&" de 4 meses",""))} | AD15: =IF(OR(X15="",X15=0),"",IF(E15+N(F15)<X15*$AD$5,"SÍ — "&TEXT(E15+N(F15),"#,##0")&" m vs "&TEXT(X15*$AD$5,"#,##0")&" m","")) | AE15: {=IF(X15="","",IF(AND(E15=0,AVERAGE(INDEX(Ventas!$C$2:$I$5000,MATCH($A15,Ventas!$A$2:$A$5000,0),0))>0,INDEX(Ventas!$J$2:$J$5000,MATCH($A15,Ventas!$A$2:$A$5000,0))<0.5*AVERAGE(INDEX(Ventas!$C$2:$I$5000,MATCH($A15,Ventas!$A$2:$A$5000,0),0))),"SÍ — stock 0 y Sep cayó (prom Feb-Ago "&TEXT(AVERAGE(INDEX(Ventas!$C$2:$I$5000,MATCH($A15,Ventas!$A$2:$A$5000,0),0)),"#,##0")&")",""))} | AF15: {=IF(X15="","",IF(AE15<>"",MAX(X15,AVERAGE(INDEX(Ventas!$C$2:$I$5000,MATCH($A15,Ventas!$A$2:$A$5000,0),0))),X15))} -> 170 | AG15: =IF(AF15="","",ROUND(AF15*4,0)-P15) -> -1280 | AH15: =IF(A15="","",IF(AF15="","SIN HISTORIAL",IF(AF15=0,"SIN VENTAS",IF(AG15>0.1*ROUND(AF15*4,0),"COMPRAR",IF(AND(-AG15>0.1*ROUND(AF15*4,0),SUM(I15:M15)+IF($AD$3="SI",SUM(N15),0)>0),"PEDIR MENOS",IF(P15/AF15>8,"SOBRESTOCK","OK")))))) -> SOBRESTOCK
A16: 4931098-0156 | B16: CAPELLADA | C16: CALI | D16: OLIVA | E16: 520 | O16: =IF(A16="","SIN SKU — cargar código para calcular",IF(X16="","SIN HISTORIAL DE VENTAS — artículo nuevo o código distinto en Ventas",IF(X16=0,IF(P16>0,"SIN VENTAS Jun-Sep — no comprar ("&TEXT(P16,"#,##0")&" m disponibles)","SIN VENTAS Jun-Sep — no comprar"),IF(AA16>0.1*Y16,"COMPRAR — faltan "&TEXT(AA16,"#,##0")&" m para 4 meses"&IF(P16-E16>0," (ya contando pedidos)",""),IF(AND(-AA16>0.1*Y16,SUM(I16:M16)+IF($AD$3="SI",SUM(N16),0)>0),"PEDIR MENOS — sobran "&TEXT(-AA16,"#,##0")&" m; revisar pedidos sin facturar ("&TEXT(SUM(I16:M16)+IF($AD$3="SI",SUM(N16),0),"#,##0")&" m)",IF(Z16>8,"SOBRESTOCK — "&TEXT(Z16,"0.0")&" meses de cobertura","OK — cubierto ("&TEXT(Z16,"0.0")&" meses)")))))) -> OK — cubierto (7.4 meses) | P16: =E16+N(F16)+SUM(G16:M16)+IF($AD$3="SI",SUM(N16),0) -> 520 | X16: =IFERROR(VLOOKUP($A16,Ventas!$A$2:$L$5000,12,FALSE()),"") -> 70 | Y16: =IF(X16="","",ROUND(X16*4,0)) -> 280 | Z16: =IF(OR(X16="",X16=0),"",ROUND(P16/X16,1)) -> 7.4 | AA16: =IF(Y16="","",Y16-P16) -> -240 | AB16: =IF(A16="","",IF(COUNTIF($A$8:$A$670,A16)>1,"DUPLICADO","")) | AC16: {=IF(AH16<>"COMPRAR","",IF(MAX(INDEX(Ventas!$G$2:$G$5000,MATCH($A16,Ventas!$A$2:$A$5000,0)),INDEX(Ventas!$H$2:$H$5000,MATCH($A16,Ventas!$A$2:$A$5000,0)),INDEX(Ventas!$I$2:$I$5000,MATCH($A16,Ventas!$A$2:$A$5000,0)),INDEX(Ventas!$J$2:$J$5000,MATCH($A16,Ventas!$A$2:$A$5000,0)))>0.5*AF16*4,"1 mes = "&TEXT(MAX(INDEX(Ventas!$G$2:$G$5000,MATCH($A16,Ventas!$A$2:$A$5000,0)),INDEX(Ventas!$H$2:$H$5000,MATCH($A16,Ventas!$A$2:$A$5000,0)),INDEX(Ventas!$I$2:$I$5000,MATCH($A16,Ventas!$A$2:$A$5000,0)),INDEX(Ventas!$J$2:$J$5000,MATCH($A16,Ventas!$A$2:$A$5000,0)))/(AF16*4),"0%")&" de 4 meses",""))} | AD16: =IF(OR(X16="",X16=0),"",IF(E16+N(F16)<X16*$AD$5,"SÍ — "&TEXT(E16+N(F16),"#,##0")&" m vs "&TEXT(X16*$AD$5,"#,##0")&" m","")) | AE16: {=IF(X16="","",IF(AND(E16=0,AVERAGE(INDEX(Ventas!$C$2:$I$5000,MATCH($A16,Ventas!$A$2:$A$5000,0),0))>0,INDEX(Ventas!$J$2:$J$5000,MATCH($A16,Ventas!$A$2:$A$5000,0))<0.5*AVERAGE(INDEX(Ventas!$C$2:$I$5000,MATCH($A16,Ventas!$A$2:$A$5000,0),0))),"SÍ — stock 0 y Sep cayó (prom Feb-Ago "&TEXT(AVERAGE(INDEX(Ventas!$C$2:$I$5000,MATCH($A16,Ventas!$A$2:$A$5000,0),0)),"#,##0")&")",""))} | AF16: {=IF(X16="","",IF(AE16<>"",MAX(X16,AVERAGE(INDEX(Ventas!$C$2:$I$5000,MATCH($A16,Ventas!$A$2:$A$5000,0),0))),X16))} -> 70 | AG16: =IF(AF16="","",ROUND(AF16*4,0)-P16) -> -240 | AH16: =IF(A16="","",IF(AF16="","SIN HISTORIAL",IF(AF16=0,"SIN VENTAS",IF(AG16>0.1*ROUND(AF16*4,0),"COMPRAR",IF(AND(-AG16>0.1*ROUND(AF16*4,0),SUM(I16:M16)+IF($AD$3="SI",SUM(N16),0)>0),"PEDIR MENOS",IF(P16/AF16>8,"SOBRESTOCK","OK")))))) -> OK
A17: 4931098-0069 | B17: CAPELLADA | C17: CALI | D17: MIEL | E17: 1893 | O17: =IF(A17="","SIN SKU — cargar código para calcular",IF(X17="","SIN HISTORIAL DE VENTAS — artículo nuevo o código distinto en Ventas",IF(X17=0,IF(P17>0,"SIN VENTAS Jun-Sep — no comprar ("&TEXT(P17,"#,##0")&" m disponibles)","SIN VENTAS Jun-Sep — no comprar"),IF(AA17>0.1*Y17,"COMPRAR — faltan "&TEXT(AA17,"#,##0")&" m para 4 meses"&IF(P17-E17>0," (ya contando pedidos)",""),IF(AND(-AA17>0.1*Y17,SUM(I17:M17)+IF($AD$3="SI",SUM(N17),0)>0),"PEDIR MENOS — sobran "&TEXT(-AA17,"#,##0")&" m; revisar pedidos sin facturar ("&TEXT(SUM(I17:M17)+IF($AD$3="SI",SUM(N17),0),"#,##0")&" m)",IF(Z17>8,"SOBRESTOCK — "&TEXT(Z17,"0.0")&" meses de cobertura","OK — cubierto ("&TEXT(Z17,"0.0")&" meses)")))))) -> SOBRESTOCK — 9.5 meses de cobertura | P17: =E17+N(F17)+SUM(G17:M17)+IF($AD$3="SI",SUM(N17),0) -> 1893 | X17: =IFERROR(VLOOKUP($A17,Ventas!$A$2:$L$5000,12,FALSE()),"") -> 200 | Y17: =IF(X17="","",ROUND(X17*4,0)) -> 800 | Z17: =IF(OR(X17="",X17=0),"",ROUND(P17/X17,1)) -> 9.5 | AA17: =IF(Y17="","",Y17-P17) -> -1093 | AB17: =IF(A17="","",IF(COUNTIF($A$8:$A$670,A17)>1,"DUPLICADO","")) | AC17: {=IF(AH17<>"COMPRAR","",IF(MAX(INDEX(Ventas!$G$2:$G$5000,MATCH($A17,Ventas!$A$2:$A$5000,0)),INDEX(Ventas!$H$2:$H$5000,MATCH($A17,Ventas!$A$2:$A$5000,0)),INDEX(Ventas!$I$2:$I$5000,MATCH($A17,Ventas!$A$2:$A$5000,0)),INDEX(Ventas!$J$2:$J$5000,MATCH($A17,Ventas!$A$2:$A$5000,0)))>0.5*AF17*4,"1 mes = "&TEXT(MAX(INDEX(Ventas!$G$2:$G$5000,MATCH($A17,Ventas!$A$2:$A$5000,0)),INDEX(Ventas!$H$2:$H$5000,MATCH($A17,Ventas!$A$2:$A$5000,0)),INDEX(Ventas!$I$2:$I$5000,MATCH($A17,Ventas!$A$2:$A$5000,0)),INDEX(Ventas!$J$2:$J$5000,MATCH($A17,Ventas!$A$2:$A$5000,0)))/(AF17*4),"0%")&" de 4 meses",""))} | AD17: =IF(OR(X17="",X17=0),"",IF(E17+N(F17)<X17*$AD$5,"SÍ — "&TEXT(E17+N(F17),"#,##0")&" m vs "&TEXT(X17*$AD$5,"#,##0")&" m","")) | AE17: {=IF(X17="","",IF(AND(E17=0,AVERAGE(INDEX(Ventas!$C$2:$I$5000,MATCH($A17,Ventas!$A$2:$A$5000,0),0))>0,INDEX(Ventas!$J$2:$J$5000,MATCH($A17,Ventas!$A$2:$A$5000,0))<0.5*AVERAGE(INDEX(Ventas!$C$2:$I$5000,MATCH($A17,Ventas!$A$2:$A$5000,0),0))),"SÍ — stock 0 y Sep cayó (prom Feb-Ago "&TEXT(AVERAGE(INDEX(Ventas!$C$2:$I$5000,MATCH($A17,Ventas!$A$2:$A$5000,0),0)),"#,##0")&")",""))} | AF17: {=IF(X17="","",IF(AE17<>"",MAX(X17,AVERAGE(INDEX(Ventas!$C$2:$I$5000,MATCH($A17,Ventas!$A$2:$A$5000,0),0))),X17))} -> 200 | AG17: =IF(AF17="","",ROUND(AF17*4,0)-P17) -> -1093 | AH17: =IF(A17="","",IF(AF17="","SIN HISTORIAL",IF(AF17=0,"SIN VENTAS",IF(AG17>0.1*ROUND(AF17*4,0),"COMPRAR",IF(AND(-AG17>0.1*ROUND(AF17*4,0),SUM(I17:M17)+IF($AD$3="SI",SUM(N17),0)>0),"PEDIR MENOS",IF(P17/AF17>8,"SOBRESTOCK","OK")))))) -> SOBRESTOCK
A18: 4931098-0019 | B18: CAPELLADA | C18: CALI | D18: NARANJA | E18: 512 | O18: =IF(A18="","SIN SKU — cargar código para calcular",IF(X18="","SIN HISTORIAL DE VENTAS — artículo nuevo o código distinto en Ventas",IF(X18=0,IF(P18>0,"SIN VENTAS Jun-Sep — no comprar ("&TEXT(P18,"#,##0")&" m disponibles)","SIN VENTAS Jun-Sep — no comprar"),IF(AA18>0.1*Y18,"COMPRAR — faltan "&TEXT(AA18,"#,##0")&" m para 4 meses"&IF(P18-E18>0," (ya contando pedidos)",""),IF(AND(-AA18>0.1*Y18,SUM(I18:M18)+IF($AD$3="SI",SUM(N18),0)>0),"PEDIR MENOS — sobran "&TEXT(-AA18,"#,##0")&" m; revisar pedidos sin facturar ("&TEXT(SUM(I18:M18)+IF($AD$3="SI",SUM(N18),0),"#,##0")&" m)",IF(Z18>8,"SOBRESTOCK — "&TEXT(Z18,"0.0")&" meses de cobertura","OK — cubierto ("&TEXT(Z18,"0.0")&" meses)")))))) -> SIN VENTAS Jun-Sep — no comprar (512 m disponibles) | P18: =E18+N(F18)+SUM(G18:M18)+IF($AD$3="SI",SUM(N18),0) -> 512 | X18: =IFERROR(VLOOKUP($A18,Ventas!$A$2:$L$5000,12,FALSE()),"") -> 0 | Y18: =IF(X18="","",ROUND(X18*4,0)) -> 0 | Z18: =IF(OR(X18="",X18=0),"",ROUND(P18/X18,1)) | AA18: =IF(Y18="","",Y18-P18) -> -512 | AB18: =IF(A18="","",IF(COUNTIF($A$8:$A$670,A18)>1,"DUPLICADO","")) | AC18: {=IF(AH18<>"COMPRAR","",IF(MAX(INDEX(Ventas!$G$2:$G$5000,MATCH($A18,Ventas!$A$2:$A$5000,0)),INDEX(Ventas!$H$2:$H$5000,MATCH($A18,Ventas!$A$2:$A$5000,0)),INDEX(Ventas!$I$2:$I$5000,MATCH($A18,Ventas!$A$2:$A$5000,0)),INDEX(Ventas!$J$2:$J$5000,MATCH($A18,Ventas!$A$2:$A$5000,0)))>0.5*AF18*4,"1 mes = "&TEXT(MAX(INDEX(Ventas!$G$2:$G$5000,MATCH($A18,Ventas!$A$2:$A$5000,0)),INDEX(Ventas!$H$2:$H$5000,MATCH($A18,Ventas!$A$2:$A$5000,0)),INDEX(Ventas!$I$2:$I$5000,MATCH($A18,Ventas!$A$2:$A$5000,0)),INDEX(Ventas!$J$2:$J$5000,MATCH($A18,Ventas!$A$2:$A$5000,0)))/(AF18*4),"0%")&" de 4 meses",""))} | AD18: =IF(OR(X18="",X18=0),"",IF(E18+N(F18)<X18*$AD$5,"SÍ — "&TEXT(E18+N(F18),"#,##0")&" m vs "&TEXT(X18*$AD$5,"#,##0")&" m","")) | AE18: {=IF(X18="","",IF(AND(E18=0,AVERAGE(INDEX(Ventas!$C$2:$I$5000,MATCH($A18,Ventas!$A$2:$A$5000,0),0))>0,INDEX(Ventas!$J$2:$J$5000,MATCH($A18,Ventas!$A$2:$A$5000,0))<0.5*AVERAGE(INDEX(Ventas!$C$2:$I$5000,MATCH($A18,Ventas!$A$2:$A$5000,0),0))),"SÍ — stock 0 y Sep cayó (prom Feb-Ago "&TEXT(AVERAGE(INDEX(Ventas!$C$2:$I$5000,MATCH($A18,Ventas!$A$2:$A$5000,0),0)),"#,##0")&")",""))} | AF18: {=IF(X18="","",IF(AE18<>"",MAX(X18,AVERAGE(INDEX(Ventas!$C$2:$I$5000,MATCH($A18,Ventas!$A$2:$A$5000,0),0))),X18))} -> 0 | AG18: =IF(AF18="","",ROUND(AF18*4,0)-P18) -> -512 | AH18: =IF(A18="","",IF(AF18="","SIN HISTORIAL",IF(AF18=0,"SIN VENTAS",IF(AG18>0.1*ROUND(AF18*4,0),"COMPRAR",IF(AND(-AG18>0.1*ROUND(AF18*4,0),SUM(I18:M18)+IF($AD$3="SI",SUM(N18),0)>0),"PEDIR MENOS",IF(P18/AF18>8,"SOBRESTOCK","OK")))))) -> SIN VENTAS
A19: 4931098-0193 | B19: CAPELLADA | C19: CALI | D19: VERDE BENETTON | E19: 440 | O19: =IF(A19="","SIN SKU — cargar código para calcular",IF(X19="","SIN HISTORIAL DE VENTAS — artículo nuevo o código distinto en Ventas",IF(X19=0,IF(P19>0,"SIN VENTAS Jun-Sep — no comprar ("&TEXT(P19,"#,##0")&" m disponibles)","SIN VENTAS Jun-Sep — no comprar"),IF(AA19>0.1*Y19,"COMPRAR — faltan "&TEXT(AA19,"#,##0")&" m para 4 meses"&IF(P19-E19>0," (ya contando pedidos)",""),IF(AND(-AA19>0.1*Y19,SUM(I19:M19)+IF($AD$3="SI",SUM(N19),0)>0),"PEDIR MENOS — sobran "&TEXT(-AA19,"#,##0")&" m; revisar pedidos sin facturar ("&TEXT(SUM(I19:M19)+IF($AD$3="SI",SUM(N19),0),"#,##0")&" m)",IF(Z19>8,"SOBRESTOCK — "&TEXT(Z19,"0.0")&" meses de cobertura","OK — cubierto ("&TEXT(Z19,"0.0")&" meses)")))))) -> SIN VENTAS Jun-Sep — no comprar (440 m disponibles) | P19: =E19+N(F19)+SUM(G19:M19)+IF($AD$3="SI",SUM(N19),0) -> 440 | X19: =IFERROR(VLOOKUP($A19,Ventas!$A$2:$L$5000,12,FALSE()),"") -> 0 | Y19: =IF(X19="","",ROUND(X19*4,0)) -> 0 | Z19: =IF(OR(X19="",X19=0),"",ROUND(P19/X19,1)) | AA19: =IF(Y19="","",Y19-P19) -> -440 | AB19: =IF(A19="","",IF(COUNTIF($A$8:$A$670,A19)>1,"DUPLICADO","")) | AC19: {=IF(AH19<>"COMPRAR","",IF(MAX(INDEX(Ventas!$G$2:$G$5000,MATCH($A19,Ventas!$A$2:$A$5000,0)),INDEX(Ventas!$H$2:$H$5000,MATCH($A19,Ventas!$A$2:$A$5000,0)),INDEX(Ventas!$I$2:$I$5000,MATCH($A19,Ventas!$A$2:$A$5000,0)),INDEX(Ventas!$J$2:$J$5000,MATCH($A19,Ventas!$A$2:$A$5000,0)))>0.5*AF19*4,"1 mes = "&TEXT(MAX(INDEX(Ventas!$G$2:$G$5000,MATCH($A19,Ventas!$A$2:$A$5000,0)),INDEX(Ventas!$H$2:$H$5000,MATCH($A19,Ventas!$A$2:$A$5000,0)),INDEX(Ventas!$I$2:$I$5000,MATCH($A19,Ventas!$A$2:$A$5000,0)),INDEX(Ventas!$J$2:$J$5000,MATCH($A19,Ventas!$A$2:$A$5000,0)))/(AF19*4),"0%")&" de 4 meses",""))} | AD19: =IF(OR(X19="",X19=0),"",IF(E19+N(F19)<X19*$AD$5,"SÍ — "&TEXT(E19+N(F19),"#,##0")&" m vs "&TEXT(X19*$AD$5,"#,##0")&" m","")) | AE19: {=IF(X19="","",IF(AND(E19=0,AVERAGE(INDEX(Ventas!$C$2:$I$5000,MATCH($A19,Ventas!$A$2:$A$5000,0),0))>0,INDEX(Ventas!$J$2:$J$5000,MATCH($A19,Ventas!$A$2:$A$5000,0))<0.5*AVERAGE(INDEX(Ventas!$C$2:$I$5000,MATCH($A19,Ventas!$A$2:$A$5000,0),0))),"SÍ — stock 0 y Sep cayó (prom Feb-Ago "&TEXT(AVERAGE(INDEX(Ventas!$C$2:$I$5000,MATCH($A19,Ventas!$A$2:$A$5000,0),0)),"#,##0")&")",""))} | AF19: {=IF(X19="","",IF(AE19<>"",MAX(X19,AVERAGE(INDEX(Ventas!$C$2:$I$5000,MATCH($A19,Ventas!$A$2:$A$5000,0),0))),X19))} -> 0 | AG19: =IF(AF19="","",ROUND(AF19*4,0)-P19) -> -440 | AH19: =IF(A19="","",IF(AF19="","SIN HISTORIAL",IF(AF19=0,"SIN VENTAS",IF(AG19>0.1*ROUND(AF19*4,0),"COMPRAR",IF(AND(-AG19>0.1*ROUND(AF19*4,0),SUM(I19:M19)+IF($AD$3="SI",SUM(N19),0)>0),"PEDIR MENOS",IF(P19/AF19>8,"SOBRESTOCK","OK")))))) -> SIN VENTAS
A20: 4931098-0008 | B20: CAPELLADA | C20: CALI | D20: CORAL | E20: 502 | O20: =IF(A20="","SIN SKU — cargar código para calcular",IF(X20="","SIN HISTORIAL DE VENTAS — artículo nuevo o código distinto en Ventas",IF(X20=0,IF(P20>0,"SIN VENTAS Jun-Sep — no comprar ("&TEXT(P20,"#,##0")&" m disponibles)","SIN VENTAS Jun-Sep — no comprar"),IF(AA20>0.1*Y20,"COMPRAR — faltan "&TEXT(AA20,"#,##0")&" m para 4 meses"&IF(P20-E20>0," (ya contando pedidos)",""),IF(AND(-AA20>0.1*Y20,SUM(I20:M20)+IF($AD$3="SI",SUM(N20),0)>0),"PEDIR MENOS — sobran "&TEXT(-AA20,"#,##0")&" m; revisar pedidos sin facturar ("&TEXT(SUM(I20:M20)+IF($AD$3="SI",SUM(N20),0),"#,##0")&" m)",IF(Z20>8,"SOBRESTOCK — "&TEXT(Z20,"0.0")&" meses de cobertura","OK — cubierto ("&TEXT(Z20,"0.0")&" meses)")))))) -> SIN VENTAS Jun-Sep — no comprar (502 m disponibles) | P20: =E20+N(F20)+SUM(G20:M20)+IF($AD$3="SI",SUM(N20),0) -> 502 | X20: =IFERROR(VLOOKUP($A20,Ventas!$A$2:$L$5000,12,FALSE()),"") -> 0 | Y20: =IF(X20="","",ROUND(X20*4,0)) -> 0 | Z20: =IF(OR(X20="",X20=0),"",ROUND(P20/X20,1)) | AA20: =IF(Y20="","",Y20-P20) -> -502 | AB20: =IF(A20="","",IF(COUNTIF($A$8:$A$670,A20)>1,"DUPLICADO","")) | AC20: {=IF(AH20<>"COMPRAR","",IF(MAX(INDEX(Ventas!$G$2:$G$5000,MATCH($A20,Ventas!$A$2:$A$5000,0)),INDEX(Ventas!$H$2:$H$5000,MATCH($A20,Ventas!$A$2:$A$5000,0)),INDEX(Ventas!$I$2:$I$5000,MATCH($A20,Ventas!$A$2:$A$5000,0)),INDEX(Ventas!$J$2:$J$5000,MATCH($A20,Ventas!$A$2:$A$5000,0)))>0.5*AF20*4,"1 mes = "&TEXT(MAX(INDEX(Ventas!$G$2:$G$5000,MATCH($A20,Ventas!$A$2:$A$5000,0)),INDEX(Ventas!$H$2:$H$5000,MATCH($A20,Ventas!$A$2:$A$5000,0)),INDEX(Ventas!$I$2:$I$5000,MATCH($A20,Ventas!$A$2:$A$5000,0)),INDEX(Ventas!$J$2:$J$5000,MATCH($A20,Ventas!$A$2:$A$5000,0)))/(AF20*4),"0%")&" de 4 meses",""))} | AD20: =IF(OR(X20="",X20=0),"",IF(E20+N(F20)<X20*$AD$5,"SÍ — "&TEXT(E20+N(F20),"#,##0")&" m vs "&TEXT(X20*$AD$5,"#,##0")&" m","")) | AE20: {=IF(X20="","",IF(AND(E20=0,AVERAGE(INDEX(Ventas!$C$2:$I$5000,MATCH($A20,Ventas!$A$2:$A$5000,0),0))>0,INDEX(Ventas!$J$2:$J$5000,MATCH($A20,Ventas!$A$2:$A$5000,0))<0.5*AVERAGE(INDEX(Ventas!$C$2:$I$5000,MATCH($A20,Ventas!$A$2:$A$5000,0),0))),"SÍ — stock 0 y Sep cayó (prom Feb-Ago "&TEXT(AVERAGE(INDEX(Ventas!$C$2:$I$5000,MATCH($A20,Ventas!$A$2:$A$5000,0),0)),"#,##0")&")",""))} | AF20: {=IF(X20="","",IF(AE20<>"",MAX(X20,AVERAGE(INDEX(Ventas!$C$2:$I$5000,MATCH($A20,Ventas!$A$2:$A$5000,0),0))),X20))} -> 0 | AG20: =IF(AF20="","",ROUND(AF20*4,0)-P20) -> -502 | AH20: =IF(A20="","",IF(AF20="","SIN HISTORIAL",IF(AF20=0,"SIN VENTAS",IF(AG20>0.1*ROUND(AF20*4,0),"COMPRAR",IF(AND(-AG20>0.1*ROUND(AF20*4,0),SUM(I20:M20)+IF($AD$3="SI",SUM(N20),0)>0),"PEDIR MENOS",IF(P20/AF20>8,"SOBRESTOCK","OK")))))) -> SIN VENTAS
A21: 4931098-0010 | B21: CAPELLADA | C21: CALI | D21: CHOCOLATE | E21: 0 | H21: 1000 | I21: 843 | K21: 3000 | O21: =IF(A21="","SIN SKU — cargar código para calcular",IF(X21="","SIN HISTORIAL DE VENTAS — artículo nuevo o código distinto en Ventas",IF(X21=0,IF(P21>0,"SIN VENTAS Jun-Sep — no comprar ("&TEXT(P21,"#,##0")&" m disponibles)","SIN VENTAS Jun-Sep — no comprar"),IF(AA21>0.1*Y21,"COMPRAR — faltan "&TEXT(AA21,"#,##0")&" m para 4 meses"&IF(P21-E21>0," (ya contando pedidos)",""),IF(AND(-AA21>0.1*Y21,SUM(I21:M21)+IF($AD$3="SI",SUM(N21),0)>0),"PEDIR MENOS — sobran "&TEXT(-AA21,"#,##0")&" m; revisar pedidos sin facturar ("&TEXT(SUM(I21:M21)+IF($AD$3="SI",SUM(N21),0),"#,##0")&" m)",IF(Z21>8,"SOBRESTOCK — "&TEXT(Z21,"0.0")&" meses de cobertura","OK — cubierto ("&TEXT(Z21,"0.0")&" meses)")))))) -> PEDIR MENOS — sobran 655 m; revisar pedidos sin facturar (3,843 m) | P21: =E21+N(F21)+SUM(G21:M21)+IF($AD$3="SI",SUM(N21),0) -> 4843 | Q21: Ingresaron 17998 mts desde agosto del año 2025 hasta junio del 2026 y no hay stock. | X21: =IFERROR(VLOOKUP($A21,Ventas!$A$2:$L$5000,12,FALSE()),"") -> 1047 | Y21: =IF(X21="","",ROUND(X21*4,0)) -> 4188 | Z21: =IF(OR(X21="",X21=0),"",ROUND(P21/X21,1)) -> 4.6 | AA21: =IF(Y21="","",Y21-P21) -> -655 | AB21: =IF(A21="","",IF(COUNTIF($A$8:$A$670,A21)>1,"DUPLICADO","")) | AC21: {=IF(AH21<>"COMPRAR","",IF(MAX(INDEX(Ventas!$G$2:$G$5000,MATCH($A21,Ventas!$A$2:$A$5000,0)),INDEX(Ventas!$H$2:$H$5000,MATCH($A21,Ventas!$A$2:$A$5000,0)),INDEX(Ventas!$I$2:$I$5000,MATCH($A21,Ventas!$A$2:$A$5000,0)),INDEX(Ventas!$J$2:$J$5000,MATCH($A21,Ventas!$A$2:$A$5000,0)))>0.5*AF21*4,"1 mes = "&TEXT(MAX(INDEX(Ventas!$G$2:$G$5000,MATCH($A21,Ventas!$A$2:$A$5000,0)),INDEX(Ventas!$H$2:$H$5000,MATCH($A21,Ventas!$A$2:$A$5000,0)),INDEX(Ventas!$I$2:$I$5000,MATCH($A21,Ventas!$A$2:$A$5000,0)),INDEX(Ventas!$J$2:$J$5000,MATCH($A21,Ventas!$A$2:$A$5000,0)))/(AF21*4),"0%")&" de 4 meses",""))} | AD21: =IF(OR(X21="",X21=0),"",IF(E21+N(F21)<X21*$AD$5,"SÍ — "&TEXT(E21+N(F21),"#,##0")&" m vs "&TEXT(X21*$AD$5,"#,##0")&" m","")) -> SÍ — 0 m vs 555 m | AE21: {=IF(X21="","",IF(AND(E21=0,AVERAGE(INDEX(Ventas!$C$2:$I$5000,MATCH($A21,Ventas!$A$2:$A$5000,0),0))>0,INDEX(Ventas!$J$2:$J$5000,MATCH($A21,Ventas!$A$2:$A$5000,0))<0.5*AVERAGE(INDEX(Ventas!$C$2:$I$5000,MATCH($A21,Ventas!$A$2:$A$5000,0),0))),"SÍ — stock 0 y Sep cayó (prom Feb-Ago "&TEXT(AVERAGE(INDEX(Ventas!$C$2:$I$5000,MATCH($A21,Ventas!$A$2:$A$5000,0),0)),"#,##0")&")",""))} -> SÍ — stock 0 y Sep cayó (prom Feb-Ago 2,504) | AF21: {=IF(X21="","",IF(AE21<>"",MAX(X21,AVERAGE(INDEX(Ventas!$C$2:$I$5000,MATCH($A21,Ventas!$A$2:$A$5000,0),0))),X21))} -> 2504.4286 | AG21: =IF(AF21="","",ROUND(AF21*4,0)-P21) -> 5175 | AH21: =IF(A21="","",IF(AF21="","SIN HISTORIAL",IF(AF21=0,"SIN VENTAS",IF(AG21>0.1*ROUND(AF21*4,0),"COMPRAR",IF(AND(-AG21>0.1*ROUND(AF21*4,0),SUM(I21:M21)+IF($AD$3="SI",SUM(N21),0)>0),"PEDIR MENOS",IF(P21/AF21>8,"SOBRESTOCK","OK")))))) -> COMPRAR
A22: 4931098-0044 | B22: CAPELLADA | C22: CALI | D22: MOCCA | E22: 2826 | O22: =IF(A22="","SIN SKU — cargar código para calcular",IF(X22="","SIN HISTORIAL DE VENTAS — artículo nuevo o código distinto en Ventas",IF(X22=0,IF(P22>0,"SIN VENTAS Jun-Sep — no comprar ("&TEXT(P22,"#,##0")&" m disponibles)","SIN VENTAS Jun-Sep — no comprar"),IF(AA22>0.1*Y22,"COMPRAR — faltan "&TEXT(AA22,"#,##0")&" m para 4 meses"&IF(P22-E22>0," (ya contando pedidos)",""),IF(AND(-AA22>0.1*Y22,SUM(I22:M22)+IF($AD$3="SI",SUM(N22),0)>0),"PEDIR MENOS — sobran "&TEXT(-AA22,"#,##0")&" m; revisar pedidos sin facturar ("&TEXT(SUM(I22:M22)+IF($AD$3="SI",SUM(N22),0),"#,##0")&" m)",IF(Z22>8,"SOBRESTOCK — "&TEXT(Z22,"0.0")&" meses de cobertura","OK — cubierto ("&TEXT(Z22,"0.0")&" meses)")))))) -> SOBRESTOCK — 70.7 meses de cobertura | P22: =E22+N(F22)+SUM(G22:M22)+IF($AD$3="SI",SUM(N22),0) -> 2826 | X22: =IFERROR(VLOOKUP($A22,Ventas!$A$2:$L$5000,12,FALSE()),"") -> 40 | Y22: =IF(X22="","",ROUND(X22*4,0)) -> 160 | Z22: =IF(OR(X22="",X22=0),"",ROUND(P22/X22,1)) -> 70.7 | AA22: =IF(Y22="","",Y22-P22) -> -2666 | AB22: =IF(A22="","",IF(COUNTIF($A$8:$A$670,A22)>1,"DUPLICADO","")) | AC22: {=IF(AH22<>"COMPRAR","",IF(MAX(INDEX(Ventas!$G$2:$G$5000,MATCH($A22,Ventas!$A$2:$A$5000,0)),INDEX(Ventas!$H$2:$H$5000,MATCH($A22,Ventas!$A$2:$A$5000,0)),INDEX(Ventas!$I$2:$I$5000,MATCH($A22,Ventas!$A$2:$A$5000,0)),INDEX(Ventas!$J$2:$J$5000,MATCH($A22,Ventas!$A$2:$A$5000,0)))>0.5*AF22*4,"1 mes = "&TEXT(MAX(INDEX(Ventas!$G$2:$G$5000,MATCH($A22,Ventas!$A$2:$A$5000,0)),INDEX(Ventas!$H$2:$H$5000,MATCH($A22,Ventas!$A$2:$A$5000,0)),INDEX(Ventas!$I$2:$I$5000,MATCH($A22,Ventas!$A$2:$A$5000,0)),INDEX(Ventas!$J$2:$J$5000,MATCH($A22,Ventas!$A$2:$A$5000,0)))/(AF22*4),"0%")&" de 4 meses",""))} | AD22: =IF(OR(X22="",X22=0),"",IF(E22+N(F22)<X22*$AD$5,"SÍ — "&TEXT(E22+N(F22),"#,##0")&" m vs "&TEXT(X22*$AD$5,"#,##0")&" m","")) | AE22: {=IF(X22="","",IF(AND(E22=0,AVERAGE(INDEX(Ventas!$C$2:$I$5000,MATCH($A22,Ventas!$A$2:$A$5000,0),0))>0,INDEX(Ventas!$J$2:$J$5000,MATCH($A22,Ventas!$A$2:$A$5000,0))<0.5*AVERAGE(INDEX(Ventas!$C$2:$I$5000,MATCH($A22,Ventas!$A$2:$A$5000,0),0))),"SÍ — stock 0 y Sep cayó (prom Feb-Ago "&TEXT(AVERAGE(INDEX(Ventas!$C$2:$I$5000,MATCH($A22,Ventas!$A$2:$A$5000,0),0)),"#,##0")&")",""))} | AF22: {=IF(X22="","",IF(AE22<>"",MAX(X22,AVERAGE(INDEX(Ventas!$C$2:$I$5000,MATCH($A22,Ventas!$A$2:$A$5000,0),0))),X22))} -> 40 | AG22: =IF(AF22="","",ROUND(AF22*4,0)-P22) -> -2666 | AH22: =IF(A22="","",IF(AF22="","SIN HISTORIAL",IF(AF22=0,"SIN VENTAS",IF(AG22>0.1*ROUND(AF22*4,0),"COMPRAR",IF(AND(-AG22>0.1*ROUND(AF22*4,0),SUM(I22:M22)+IF($AD$3="SI",SUM(N22),0)>0),"PEDIR MENOS",IF(P22/AF22>8,"SOBRESTOCK","OK")))))) -> SOBRESTOCK
A23: 581923-9999 | B23: CAPELLADA | C23: BOGOTA | D23: NEGRO ( Base Tejida ) | E23: 0 | H23: 1880 | I23: 4082 | K23: 6000 | L23: 6000 | O23: =IF(A23="","SIN SKU — cargar código para calcular",IF(X23="","SIN HISTORIAL DE VENTAS — artículo nuevo o código distinto en Ventas",IF(X23=0,IF(P23>0,"SIN VENTAS Jun-Sep — no comprar ("&TEXT(P23,"#,##0")&" m disponibles)","SIN VENTAS Jun-Sep — no comprar"),IF(AA23>0.1*Y23,"COMPRAR — faltan "&TEXT(AA23,"#,##0")&" m para 4 meses"&IF(P23-E23>0," (ya contando pedidos)",""),IF(AND(-AA23>0.1*Y23,SUM(I23:M23)+IF($AD$3="SI",SUM(N23),0)>0),"PEDIR MENOS — sobran "&TEXT(-AA23,"#,##0")&" m; revisar pedidos sin facturar ("&TEXT(SUM(I23:M23)+IF($AD$3="SI",SUM(N23),0),"#,##0")&" m)",IF(Z23>8,"SOBRESTOCK — "&TEXT(Z23,"0.0")&" meses de cobertura","OK — cubierto ("&TEXT(Z23,"0.0")&" meses)")))))) -> PEDIR MENOS — sobran 7,380 m; revisar pedidos sin facturar (16,082 m) | P23: =E23+N(F23)+SUM(G23:M23)+IF($AD$3="SI",SUM(N23),0) -> 17962 | Q23: 10000 | X23: =IFERROR(VLOOKUP($A23,Ventas!$A$2:$L$5000,12,FALSE()),"") -> 2645.5 | Y23: =IF(X23="","",ROUND(X23*4,0)) -> 10582 | Z23: =IF(OR(X23="",X23=0),"",ROUND(P23/X23,1)) -> 6.8 | AA23: =IF(Y23="","",Y23-P23) -> -7380 | AB23: =IF(A23="","",IF(COUNTIF($A$8:$A$670,A23)>1,"DUPLICADO","")) | AC23: {=IF(AH23<>"COMPRAR","",IF(MAX(INDEX(Ventas!$G$2:$G$5000,MATCH($A23,Ventas!$A$2:$A$5000,0)),INDEX(Ventas!$H$2:$H$5000,MATCH($A23,Ventas!$A$2:$A$5000,0)),INDEX(Ventas!$I$2:$I$5000,MATCH($A23,Ventas!$A$2:$A$5000,0)),INDEX(Ventas!$J$2:$J$5000,MATCH($A23,Ventas!$A$2:$A$5000,0)))>0.5*AF23*4,"1 mes = "&TEXT(MAX(INDEX(Ventas!$G$2:$G$5000,MATCH($A23,Ventas!$A$2:$A$5000,0)),INDEX(Ventas!$H$2:$H$5000,MATCH($A23,Ventas!$A$2:$A$5000,0)),INDEX(Ventas!$I$2:$I$5000,MATCH($A23,Ventas!$A$2:$A$5000,0)),INDEX(Ventas!$J$2:$J$5000,MATCH($A23,Ventas!$A$2:$A$5000,0)))/(AF23*4),"0%")&" de 4 meses",""))} | AD23: =IF(OR(X23="",X23=0),"",IF(E23+N(F23)<X23*$AD$5,"SÍ — "&TEXT(E23+N(F23),"#,##0")&" m vs "&TEXT(X23*$AD$5,"#,##0")&" m","")) -> SÍ — 0 m vs 1,402 m | AE23: {=IF(X23="","",IF(AND(E23=0,AVERAGE(INDEX(Ventas!$C$2:$I$5000,MATCH($A23,Ventas!$A$2:$A$5000,0),0))>0,INDEX(Ventas!$J$2:$J$5000,MATCH($A23,Ventas!$A$2:$A$5000,0))<0.5*AVERAGE(INDEX(Ventas!$C$2:$I$5000,MATCH($A23,Ventas!$A$2:$A$5000,0),0))),"SÍ — stock 0 y Sep cayó (prom Feb-Ago "&TEXT(AVERAGE(INDEX(Ventas!$C$2:$I$5000,MATCH($A23,Ventas!$A$2:$A$5000,0),0)),"#,##0")&")",""))} | AF23: {=IF(X23="","",IF(AE23<>"",MAX(X23,AVERAGE(INDEX(Ventas!$C$2:$I$5000,MATCH($A23,Ventas!$A$2:$A$5000,0),0))),X23))} -> 2645.5 | AG23: =IF(AF23="","",ROUND(AF23*4,0)-P23) -> -7380 | AH23: =IF(A23="","",IF(AF23="","SIN HISTORIAL",IF(AF23=0,"SIN VENTAS",IF(AG23>0.1*ROUND(AF23*4,0),"COMPRAR",IF(AND(-AG23>0.1*ROUND(AF23*4,0),SUM(I23:M23)+IF($AD$3="SI",SUM(N23),0)>0),"PEDIR MENOS",IF(P23/AF23>8,"SOBRESTOCK","OK")))))) -> PEDIR MENOS
A24: 581923-0000 | B24: CAPELLADA | C24: BOGOTA | D24: BLANCO | E24: 0 | H24: 1000 | I24: 1199 | O24: =IF(A24="","SIN SKU — cargar código para calcular",IF(X24="","SIN HISTORIAL DE VENTAS — artículo nuevo o código distinto en Ventas",IF(X24=0,IF(P24>0,"SIN VENTAS Jun-Sep — no comprar ("&TEXT(P24,"#,##0")&" m disponibles)","SIN VENTAS Jun-Sep — no comprar"),IF(AA24>0.1*Y24,"COMPRAR — faltan "&TEXT(AA24,"#,##0")&" m para 4 meses"&IF(P24-E24>0," (ya contando pedidos)",""),IF(AND(-AA24>0.1*Y24,SUM(I24:M24)+IF($AD$3="SI",SUM(N24),0)>0),"PEDIR MENOS — sobran "&TEXT(-AA24,"#,##0")&" m; revisar pedidos sin facturar ("&TEXT(SUM(I24:M24)+IF($AD$3="SI",SUM(N24),0),"#,##0")&" m)",IF(Z24>8,"SOBRESTOCK — "&TEXT(Z24,"0.0")&" meses de cobertura","OK — cubierto ("&TEXT(Z24,"0.0")&" meses)")))))) -> SIN HISTORIAL DE VENTAS — artículo nuevo o código distinto en Ventas | P24: =E24+N(F24)+SUM(G24:M24)+IF($AD$3="SI",SUM(N24),0) -> 2199 | Q24: 10000 | X24: =IFERROR(VLOOKUP($A24,Ventas!$A$2:$L$5000,12,FALSE()),"") | Y24: =IF(X24="","",ROUND(X24*4,0)) | Z24: =IF(OR(X24="",X24=0),"",ROUND(P24/X24,1)) | AA24: =IF(Y24="","",Y24-P24) | AB24: =IF(A24="","",IF(COUNTIF($A$8:$A$670,A24)>1,"DUPLICADO","")) | AC24: {=IF(AH24<>"COMPRAR","",IF(MAX(INDEX(Ventas!$G$2:$G$5000,MATCH($A24,Ventas!$A$2:$A$5000,0)),INDEX(Ventas!$H$2:$H$5000,MATCH($A24,Ventas!$A$2:$A$5000,0)),INDEX(Ventas!$I$2:$I$5000,MATCH($A24,Ventas!$A$2:$A$5000,0)),INDEX(Ventas!$J$2:$J$5000,MATCH($A24,Ventas!$A$2:$A$5000,0)))>0.5*AF24*4,"1 mes = "&TEXT(MAX(INDEX(Ventas!$G$2:$G$5000,MATCH($A24,Ventas!$A$2:$A$5000,0)),INDEX(Ventas!$H$2:$H$5000,MATCH($A24,Ventas!$A$2:$A$5000,0)),INDEX(Ventas!$I$2:$I$5000,MATCH($A24,Ventas!$A$2:$A$5000,0)),INDEX(Ventas!$J$2:$J$5000,MATCH($A24,Ventas!$A$2:$A$5000,0)))/(AF24*4),"0%")&" de 4 meses",""))} | AD24: =IF(OR(X24="",X24=0),"",IF(E24+N(F24)<X24*$AD$5,"SÍ — "&TEXT(E24+N(F24),"#,##0")&" m vs "&TEXT(X24*$AD$5,"#,##0")&" m","")) | AE24: {=IF(X24="","",IF(AND(E24=0,AVERAGE(INDEX(Ventas!$C$2:$I$5000,MATCH($A24,Ventas!$A$2:$A$5000,0),0))>0,INDEX(Ventas!$J$2:$J$5000,MATCH($A24,Ventas!$A$2:$A$5000,0))<0.5*AVERAGE(INDEX(Ventas!$C$2:$I$5000,MATCH($A24,Ventas!$A$2:$A$5000,0),0))),"SÍ — stock 0 y Sep cayó (prom Feb-Ago "&TEXT(AVERAGE(INDEX(Ventas!$C$2:$I$5000,MATCH($A24,Ventas!$A$2:$A$5000,0),0)),"#,##0")&")",""))} | AF24: {=IF(X24="","",IF(AE24<>"",MAX(X24,AVERAGE(INDEX(Ventas!$C$2:$I$5000,MATCH($A24,Ventas!$A$2:$A$5000,0),0))),X24))} | AG24: =IF(AF24="","",ROUND(AF24*4,0)-P24) | AH24: =IF(A24="","",IF(AF24="","SIN HISTORIAL",IF(AF24=0,"SIN VENTAS",IF(AG24>0.1*ROUND(AF24*4,0),"COMPRAR",IF(AND(-AG24>0.1*ROUND(AF24*4,0),SUM(I24:M24)+IF($AD$3="SI",SUM(N24),0)>0),"PEDIR MENOS",IF(P24/AF24>8,"SOBRESTOCK","OK")))))) -> SIN HISTORIAL
A25: 581923-0010 | B25: CAPELLADA | C25: BOGOTA | D25: CHOCOLATE | E25: 0 | H25: 1000 | I25: 1079 | K25: 2000 | O25: =IF(A25="","SIN SKU — cargar código para calcular",IF(X25="","SIN HISTORIAL DE VENTAS — artículo nuevo o código distinto en Ventas",IF(X25=0,IF(P25>0,"SIN VENTAS Jun-Sep — no comprar ("&TEXT(P25,"#,##0")&" m disponibles)","SIN VENTAS Jun-Sep — no comprar"),IF(AA25>0.1*Y25,"COMPRAR — faltan "&TEXT(AA25,"#,##0")&" m para 4 meses"&IF(P25-E25>0," (ya contando pedidos)",""),IF(AND(-AA25>0.1*Y25,SUM(I25:M25)+IF($AD$3="SI",SUM(N25),0)>0),"PEDIR MENOS — sobran "&TEXT(-AA25,"#,##0")&" m; revisar pedidos sin facturar ("&TEXT(SUM(I25:M25)+IF($AD$3="SI",SUM(N25),0),"#,##0")&" m)",IF(Z25>8,"SOBRESTOCK — "&TEXT(Z25,"0.0")&" meses de cobertura","OK — cubierto ("&TEXT(Z25,"0.0")&" meses)")))))) -> COMPRAR — faltan 1,382 m para 4 meses (ya contando pedidos) | P25: =E25+N(F25)+SUM(G25:M25)+IF($AD$3="SI",SUM(N25),0) -> 4079 | Q25: En lo que va del 2026 ingresaron 7936 mts y se vendió todo. | X25: =IFERROR(VLOOKUP($A25,Ventas!$A$2:$L$5000,12,FALSE()),"") -> 1365.25 | Y25: =IF(X25="","",ROUND(X25*4,0)) -> 5461 | Z25: =IF(OR(X25="",X25=0),"",ROUND(P25/X25,1)) -> 3 | AA25: =IF(Y25="","",Y25-P25) -> 1382 | AB25: =IF(A25="","",IF(COUNTIF($A$8:$A$670,A25)>1,"DUPLICADO","")) | AC25: {=IF(AH25<>"COMPRAR","",IF(MAX(INDEX(Ventas!$G$2:$G$5000,MATCH($A25,Ventas!$A$2:$A$5000,0)),INDEX(Ventas!$H$2:$H$5000,MATCH($A25,Ventas!$A$2:$A$5000,0)),INDEX(Ventas!$I$2:$I$5000,MATCH($A25,Ventas!$A$2:$A$5000,0)),INDEX(Ventas!$J$2:$J$5000,MATCH($A25,Ventas!$A$2:$A$5000,0)))>0.5*AF25*4,"1 mes = "&TEXT(MAX(INDEX(Ventas!$G$2:$G$5000,MATCH($A25,Ventas!$A$2:$A$5000,0)),INDEX(Ventas!$H$2:$H$5000,MATCH($A25,Ventas!$A$2:$A$5000,0)),INDEX(Ventas!$I$2:$I$5000,MATCH($A25,Ventas!$A$2:$A$5000,0)),INDEX(Ventas!$J$2:$J$5000,MATCH($A25,Ventas!$A$2:$A$5000,0)))/(AF25*4),"0%")&" de 4 meses",""))} | AD25: =IF(OR(X25="",X25=0),"",IF(E25+N(F25)<X25*$AD$5,"SÍ — "&TEXT(E25+N(F25),"#,##0")&" m vs "&TEXT(X25*$AD$5,"#,##0")&" m","")) -> SÍ — 0 m vs 724 m | AE25: {=IF(X25="","",IF(AND(E25=0,AVERAGE(INDEX(Ventas!$C$2:$I$5000,MATCH($A25,Ventas!$A$2:$A$5000,0),0))>0,INDEX(Ventas!$J$2:$J$5000,MATCH($A25,Ventas!$A$2:$A$5000,0))<0.5*AVERAGE(INDEX(Ventas!$C$2:$I$5000,MATCH($A25,Ventas!$A$2:$A$5000,0),0))),"SÍ — stock 0 y Sep cayó (prom Feb-Ago "&TEXT(AVERAGE(INDEX(Ventas!$C$2:$I$5000,MATCH($A25,Ventas!$A$2:$A$5000,0),0)),"#,##0")&")",""))} -> SÍ — stock 0 y Sep cayó (prom Feb-Ago 1,145) | AF25: {=IF(X25="","",IF(AE25<>"",MAX(X25,AVERAGE(INDEX(Ventas!$C$2:$I$5000,MATCH($A25,Ventas!$A$2:$A$5000,0),0))),X25))} -> 1365.25 | AG25: =IF(AF25="","",ROUND(AF25*4,0)-P25) -> 1382 | AH25: =IF(A25="","",IF(AF25="","SIN HISTORIAL",IF(AF25=0,"SIN VENTAS",IF(AG25>0.1*ROUND(AF25*4,0),"COMPRAR",IF(AND(-AG25>0.1*ROUND(AF25*4,0),SUM(I25:M25)+IF($AD$3="SI",SUM(N25),0)>0),"PEDIR MENOS",IF(P25/AF25>8,"SOBRESTOCK","OK")))))) -> COMPRAR
A26: 581923-0047 | B26: CAPELLADA | C26: BOGOTA | D26: VISON | E26: 40 | O26: =IF(A26="","SIN SKU — cargar código para calcular",IF(X26="","SIN HISTORIAL DE VENTAS — artículo nuevo o código distinto en Ventas",IF(X26=0,IF(P26>0,"SIN VENTAS Jun-Sep — no comprar ("&TEXT(P26,"#,##0")&" m disponibles)","SIN VENTAS Jun-Sep — no comprar"),IF(AA26>0.1*Y26,"COMPRAR — faltan "&TEXT(AA26,"#,##0")&" m para 4 meses"&IF(P26-E26>0," (ya contando pedidos)",""),IF(AND(-AA26>0.1*Y26,SUM(I26:M26)+IF($AD$3="SI",SUM(N26),0)>0),"PEDIR MENOS — sobran "&TEXT(-AA26,"#,##0")&" m; revisar pedidos sin facturar ("&TEXT(SUM(I26:M26)+IF($AD$3="SI",SUM(N26),0),"#,##0")&" m)",IF(Z26>8,"SOBRESTOCK — "&TEXT(Z26,"0.0")&" meses de cobertura","OK — cubierto ("&TEXT(Z26,"0.0")&" meses)")))))) -> COMPRAR — faltan 226 m para 4 meses | P26: =E26+N(F26)+SUM(G26:M26)+IF($AD$3="SI",SUM(N26),0) -> 40 | X26: =IFERROR(VLOOKUP($A26,Ventas!$A$2:$L$5000,12,FALSE()),"") -> 66.5 | Y26: =IF(X26="","",ROUND(X26*4,0)) -> 266 | Z26: =IF(OR(X26="",X26=0),"",ROUND(P26/X26,1)) -> 0.6 | AA26: =IF(Y26="","",Y26-P26) -> 226 | AB26: =IF(A26="","",IF(COUNTIF($A$8:$A$670,A26)>1,"DUPLICADO","")) | AC26: {=IF(AH26<>"COMPRAR","",IF(MAX(INDEX(Ventas!$G$2:$G$5000,MATCH($A26,Ventas!$A$2:$A$5000,0)),INDEX(Ventas!$H$2:$H$5000,MATCH($A26,Ventas!$A$2:$A$5000,0)),INDEX(Ventas!$I$2:$I$5000,MATCH($A26,Ventas!$A$2:$A$5000,0)),INDEX(Ventas!$J$2:$J$5000,MATCH($A26,Ventas!$A$2:$A$5000,0)))>0.5*AF26*4,"1 mes = "&TEXT(MAX(INDEX(Ventas!$G$2:$G$5000,MATCH($A26,Ventas!$A$2:$A$5000,0)),INDEX(Ventas!$H$2:$H$5000,MATCH($A26,Ventas!$A$2:$A$5000,0)),INDEX(Ventas!$I$2:$I$5000,MATCH($A26,Ventas!$A$2:$A$5000,0)),INDEX(Ventas!$J$2:$J$5000,MATCH($A26,Ventas!$A$2:$A$5000,0)))/(AF26*4),"0%")&" de 4 meses",""))} -> 1 mes = 100% de 4 meses | AD26: =IF(OR(X26="",X26=0),"",IF(E26+N(F26)<X26*$AD$5,"SÍ — "&TEXT(E26+N(F26),"#,##0")&" m vs "&TEXT(X26*$AD$5,"#,##0")&" m","")) | AE26: {=IF(X26="","",IF(AND(E26=0,AVERAGE(INDEX(Ventas!$C$2:$I$5000,MATCH($A26,Ventas!$A$2:$A$5000,0),0))>0,INDEX(Ventas!$J$2:$J$5000,MATCH($A26,Ventas!$A$2:$A$5000,0))<0.5*AVERAGE(INDEX(Ventas!$C$2:$I$5000,MATCH($A26,Ventas!$A$2:$A$5000,0),0))),"SÍ — stock 0 y Sep cayó (prom Feb-Ago "&TEXT(AVERAGE(INDEX(Ventas!$C$2:$I$5000,MATCH($A26,Ventas!$A$2:$A$5000,0),0)),"#,##0")&")",""))} | AF26: {=IF(X26="","",IF(AE26<>"",MAX(X26,AVERAGE(INDEX(Ventas!$C$2:$I$5000,MATCH($A26,Ventas!$A$2:$A$5000,0),0))),X26))} -> 66.5 | AG26: =IF(AF26="","",ROUND(AF26*4,0)-P26) -> 226 | AH26: =IF(A26="","",IF(AF26="","SIN HISTORIAL",IF(AF26=0,"SIN VENTAS",IF(AG26>0.1*ROUND(AF26*4,0),"COMPRAR",IF(AND(-AG26>0.1*ROUND(AF26*4,0),SUM(I26:M26)+IF($AD$3="SI",SUM(N26),0)>0),"PEDIR MENOS",IF(P26/AF26>8,"SOBRESTOCK","OK")))))) -> COMPRAR
A27: 5081098-9999 | B27: PU BONDEADO | C27: MILAN | D27: NEGRO | E27: 4552 | O27: =IF(A27="","SIN SKU — cargar código para calcular",IF(X27="","SIN HISTORIAL DE VENTAS — artículo nuevo o código distinto en Ventas",IF(X27=0,IF(P27>0,"SIN VENTAS Jun-Sep — no comprar ("&TEXT(P27,"#,##0")&" m disponibles)","SIN VENTAS Jun-Sep — no comprar"),IF(AA27>0.1*Y27,"COMPRAR — faltan "&TEXT(AA27,"#,##0")&" m para 4 meses"&IF(P27-E27>0," (ya contando pedidos)",""),IF(AND(-AA27>0.1*Y27,SUM(I27:M27)+IF($AD$3="SI",SUM(N27),0)>0),"PEDIR MENOS — sobran "&TEXT(-AA27,"#,##0")&" m; revisar pedidos sin facturar ("&TEXT(SUM(I27:M27)+IF($AD$3="SI",SUM(N27),0),"#,##0")&" m)",IF(Z27>8,"SOBRESTOCK — "&TEXT(Z27,"0.0")&" meses de cobertura","OK — cubierto ("&TEXT(Z27,"0.0")&" meses)")))))) -> SOBRESTOCK — 606.9 meses de cobertura | P27: =E27+N(F27)+SUM(G27:M27)+IF($AD$3="SI",SUM(N27),0) -> 4552 | X27: =IFERROR(VLOOKUP($A27,Ventas!$A$2:$L$5000,12,FALSE()),"") -> 7.5 | Y27: =IF(X27="","",ROUND(X27*4,0)) -> 30 | Z27: =IF(OR(X27="",X27=0),"",ROUND(P27/X27,1)) -> 606.9 | AA27: =IF(Y27="","",Y27-P27) -> -4522 | AB27: =IF(A27="","",IF(COUNTIF($A$8:$A$670,A27)>1,"DUPLICADO","")) | AC27: {=IF(AH27<>"COMPRAR","",IF(MAX(INDEX(Ventas!$G$2:$G$5000,MATCH($A27,Ventas!$A$2:$A$5000,0)),INDEX(Ventas!$H$2:$H$5000,MATCH($A27,Ventas!$A$2:$A$5000,0)),INDEX(Ventas!$I$2:$I$5000,MATCH($A27,Ventas!$A$2:$A$5000,0)),INDEX(Ventas!$J$2:$J$5000,MATCH($A27,Ventas!$A$2:$A$5000,0)))>0.5*AF27*4,"1 mes = "&TEXT(MAX(INDEX(Ventas!$G$2:$G$5000,MATCH($A27,Ventas!$A$2:$A$5000,0)),INDEX(Ventas!$H$2:$H$5000,MATCH($A27,Ventas!$A$2:$A$5000,0)),INDEX(Ventas!$I$2:$I$5000,MATCH($A27,Ventas!$A$2:$A$5000,0)),INDEX(Ventas!$J$2:$J$5000,MATCH($A27,Ventas!$A$2:$A$5000,0)))/(AF27*4),"0%")&" de 4 meses",""))} | AD27: =IF(OR(X27="",X27=0),"",IF(E27+N(F27)<X27*$AD$5,"SÍ — "&TEXT(E27+N(F27),"#,##0")&" m vs "&TEXT(X27*$AD$5,"#,##0")&" m","")) | AE27: {=IF(X27="","",IF(AND(E27=0,AVERAGE(INDEX(Ventas!$C$2:$I$5000,MATCH($A27,Ventas!$A$2:$A$5000,0),0))>0,INDEX(Ventas!$J$2:$J$5000,MATCH($A27,Ventas!$A$2:$A$5000,0))<0.5*AVERAGE(INDEX(Ventas!$C$2:$I$5000,MATCH($A27,Ventas!$A$2:$A$5000,0),0))),"SÍ — stock 0 y Sep cayó (prom Feb-Ago "&TEXT(AVERAGE(INDEX(Ventas!$C$2:$I$5000,MATCH($A27,Ventas!$A$2:$A$5000,0),0)),"#,##0")&")",""))} | AF27: {=IF(X27="","",IF(AE27<>"",MAX(X27,AVERAGE(INDEX(Ventas!$C$2:$I$5000,MATCH($A27,Ventas!$A$2:$A$5000,0),0))),X27))} -> 7.5 | AG27: =IF(AF27="","",ROUND(AF27*4,0)-P27) -> -4522 | AH27: =IF(A27="","",IF(AF27="","SIN HISTORIAL",IF(AF27=0,"SIN VENTAS",IF(AG27>0.1*ROUND(AF27*4,0),"COMPRAR",IF(AND(-AG27>0.1*ROUND(AF27*4,0),SUM(I27:M27)+IF($AD$3="SI",SUM(N27),0)>0),"PEDIR MENOS",IF(P27/AF27>8,"SOBRESTOCK","OK")))))) -> SOBRESTOCK
A28: 5089923-0000 | B28: PU BONDEADO | C28: TURIN EVA PIQUE | D28: BLANCO | E28: 845 | O28: =IF(A28="","SIN SKU — cargar código para calcular",IF(X28="","SIN HISTORIAL DE VENTAS — artículo nuevo o código distinto en Ventas",IF(X28=0,IF(P28>0,"SIN VENTAS Jun-Sep — no comprar ("&TEXT(P28,"#,##0")&" m disponibles)","SIN VENTAS Jun-Sep — no comprar"),IF(AA28>0.1*Y28,"COMPRAR — faltan "&TEXT(AA28,"#,##0")&" m para 4 meses"&IF(P28-E28>0," (ya contando pedidos)",""),IF(AND(-AA28>0.1*Y28,SUM(I28:M28)+IF($AD$3="SI",SUM(N28),0)>0),"PEDIR MENOS — sobran "&TEXT(-AA28,"#,##0")&" m; revisar pedidos sin facturar ("&TEXT(SUM(I28:M28)+IF($AD$3="SI",SUM(N28),0),"#,##0")&" m)",IF(Z28>8,"SOBRESTOCK — "&TEXT(Z28,"0.0")&" meses de cobertura","OK — cubierto ("&TEXT(Z28,"0.0")&" meses)")))))) -> SOBRESTOCK — 56.3 meses de cobertura | P28: =E28+N(F28)+SUM(G28:M28)+IF($AD$3="SI",SUM(N28),0) -> 845 | X28: =IFERROR(VLOOKUP($A28,Ventas!$A$2:$L$5000,12,FALSE()),"") -> 15 | Y28: =IF(X28="","",ROUND(X28*4,0)) -> 60 | Z28: =IF(OR(X28="",X28=0),"",ROUND(P28/X28,1)) -> 56.3 | AA28: =IF(Y28="","",Y28-P28) -> -785 | AB28: =IF(A28="","",IF(COUNTIF($A$8:$A$670,A28)>1,"DUPLICADO","")) | AC28: {=IF(AH28<>"COMPRAR","",IF(MAX(INDEX(Ventas!$G$2:$G$5000,MATCH($A28,Ventas!$A$2:$A$5000,0)),INDEX(Ventas!$H$2:$H$5000,MATCH($A28,Ventas!$A$2:$A$5000,0)),INDEX(Ventas!$I$2:$I$5000,MATCH($A28,Ventas!$A$2:$A$5000,0)),INDEX(Ventas!$J$2:$J$5000,MATCH($A28,Ventas!$A$2:$A$5000,0)))>0.5*AF28*4,"1 mes = "&TEXT(MAX(INDEX(Ventas!$G$2:$G$5000,MATCH($A28,Ventas!$A$2:$A$5000,0)),INDEX(Ventas!$H$2:$H$5000,MATCH($A28,Ventas!$A$2:$A$5000,0)),INDEX(Ventas!$I$2:$I$5000,MATCH($A28,Ventas!$A$2:$A$5000,0)),INDEX(Ventas!$J$2:$J$5000,MATCH($A28,Ventas!$A$2:$A$5000,0)))/(AF28*4),"0%")&" de 4 meses",""))} | AD28: =IF(OR(X28="",X28=0),"",IF(E28+N(F28)<X28*$AD$5,"SÍ — "&TEXT(E28+N(F28),"#,##0")&" m vs "&TEXT(X28*$AD$5,"#,##0")&" m","")) | AE28: {=IF(X28="","",IF(AND(E28=0,AVERAGE(INDEX(Ventas!$C$2:$I$5000,MATCH($A28,Ventas!$A$2:$A$5000,0),0))>0,INDEX(Ventas!$J$2:$J$5000,MATCH($A28,Ventas!$A$2:$A$5000,0))<0.5*AVERAGE(INDEX(Ventas!$C$2:$I$5000,MATCH($A28,Ventas!$A$2:$A$5000,0),0))),"SÍ — stock 0 y Sep cayó (prom Feb-Ago "&TEXT(AVERAGE(INDEX(Ventas!$C$2:$I$5000,MATCH($A28,Ventas!$A$2:$A$5000,0),0)),"#,##0")&")",""))} | AF28: {=IF(X28="","",IF(AE28<>"",MAX(X28,AVERAGE(INDEX(Ventas!$C$2:$I$5000,MATCH($A28,Ventas!$A$2:$A$5000,0),0))),X28))} -> 15 | AG28: =IF(AF28="","",ROUND(AF28*4,0)-P28) -> -785 | AH28: =IF(A28="","",IF(AF28="","SIN HISTORIAL",IF(AF28=0,"SIN VENTAS",IF(AG28>0.1*ROUND(AF28*4,0),"COMPRAR",IF(AND(-AG28>0.1*ROUND(AF28*4,0),SUM(I28:M28)+IF($AD$3="SI",SUM(N28),0)>0),"PEDIR MENOS",IF(P28/AF28>8,"SOBRESTOCK","OK")))))) -> SOBRESTOCK
